Workbook
Name SegmentaciónDeDatos_Grupo2: #REF!
Name SlicerCache_Table_1_Col_4: #N/A
Name SlicerCache_Table_2_Col_4: #N/A
Name SlicerCache_Table_3_Col_4: #N/A
Name SlicerCache_Table_4_Col_4: #N/A
Name SlicerCache_Table_5_Col_4: #N/A
Name SlicerCache_Table_6_Col_4: #N/A

Sheet P101
D1: P101 | F1: Coevaluaciones | I1: Actividades Práctico-Experimental (APE) (30%) | V1: AVANCES (15%) | Y1: VALIDACION INDIVIDUAL (10%) | AD1: VALIDACION DE PROTOTIPO (10%) | AH1: PROTOTIPO (5%) | AK1: EXPOSICION Y DEFENSA (20%) | AO1: REPORTE (10%) | AP1: TOTAL (100%)
A2: Correo | B2: Número de Matrícula | C2: Apellidos y Nombres | D2: Grupo | E2: Vez | F2: WF1 (APE) | G2: WF2 (AVANCE) | H2: WF3 (FINALES) | I2: CL1 | J2: HT1 | K2: RPAPE1 | L2: APE1 | M2: CL2 | N2: HT2 | O2: RPAPE2 | P2: APE2 | Q2: CL3 | R2: HT3 | S2: RPAPE3 | T2: APE3 | U2: APE_total | V2: AV1 | W2: AV2 | X2: AV_total | Y2: VI1 | Z2: VI2 | AA2: VI3 | AB2: VI_STATUS | AC2: VI_TOTAL | AD2: VP1 | AE2: VP2 | AF2: VP_STATUS | AG2: VP_TOTAL | AH2: EV1_P | AI2: EV2_P | AJ2: PROT_TOTAL | AK2: POSTER | AL2: JUR_1 | AM2: JUR_2 | AN2: EXP_TOTAL | AO2: REPORTE | AP2: EXP | AQ2: PROY | AR2: AL ACADEMICO
A3: correo prueba | B3: matrícula prueba | C3: Estudiante de Prueba | D3: 0 | E3: 1 | F3: 1 | G3: 1 | H3: 1 | I3: 3 | J3: 2 | K3: 5 | L3: =SUM('P101'!$I3:$K3) -> 10 | M3: 3 | N3: 2 | O3: 5 | P3: =SUM('P101'!$M3:$O3) -> 10 | Q3: 3 | R3: 2 | S3: 5 | T3: =SUM('P101'!$Q3:$S3) -> 10 | U3: =('P101'!$L3+'P101'!$P3+'P101'!$T3)*'P101'!$F3 -> 30 | V3: 5 | W3: 10 | X3: =SUM('P101'!$V3:$W3)*'P101'!$G3 -> 15 | Y3: 2 | Z3: 3 | AA3: 5 | AB3: =IF(SUM('P101'!$Y3:$AA3)>5.9,"SI","NO") -> SI | AC3: =SUM('P101'!$Y3:$AA3) -> 10 | AD3: 2 | AE3: 8 | AF3: =IF('P101'!$AG3>5.9,"SI","NO") -> SI | AG3: =SUM('P101'!$AD3:$AE3) -> 10 | AH3: 5 | AI3: 5 | AJ3: =AVERAGE('P101'!$AH3:$AI3)*'P101'!$H3 -> 5 | AK3: 1 | AL3: 10 | AM3: 10 | AN3: =(('P101'!$AL3+'P101'!$AM3))*'P101'!$AK3 -> 20 | AO3: 10 | AP3: =SUM('P101'!$U3) -> 30 | AQ3: =SUM(AN3,AJ3,AG3,AC3,X3,'P101'!$AO3) -> 70 | AR3: ='P101'!$AP3+'P101'!$AQ3 -> 100
A4: josualme@espol.edu.ec | B4: 202509725 | C4: ALMEIDA MACIAS JOSUE DAVID | D4: 7 | F4: 1 | G4: 1.0050378 | H4: 1.0200306 | I4: 3 | J4: 0.75 | K4: 3.55 | L4: =SUM('P101'!$I4:$K4) -> 7.3 | M4: 3 | N4: 2 | O4: 5 | P4: =SUM('P101'!$M4:$O4) -> 10 | Q4: 1.5 | R4: 1.25 | S4: 0 | T4: =SUM('P101'!$Q4:$S4) -> 2.75 | U4: =('P101'!$L4+'P101'!$P4+'P101'!$T4)*'P101'!$F4 -> 20.05 | V4: 4.2 | W4: 7.3 | X4: =SUM('P101'!$V4:$W4)*'P101'!$G4 -> 11.557935 | Y4: 1 | Z4: 1.5 | AA4: 3.75 | AB4: =IF(SUM('P101'!$Y4:$AA4)>5.9,"SI","NO") -> SI | AC4: =SUM('P101'!$Y4:$AA4) -> 6.25 | AD4: 1.5 | AE4: 0 | AF4: =IF('P101'!$AG4>5.9,"SI","NO") -> NO | AG4: =SUM('P101'!$AD4:$AE4) -> 1.5 | AH4: 0 | AI4: 0 | AJ4: =AVERAGE('P101'!$AH4:$AI4)*'P101'!$H4 -> 0 | AK4: 0 | AL4: 0 | AM4: 0 | AN4: =(('P101'!$AL4+'P101'!$AM4))*'P101'!$AK4 -> 0 | AO4: 0 | AP4: =SUM('P101'!$U4) -> 20.05 | AQ4: =SUM(AN4,AJ4,AG4,AC4,X4,'P101'!$AO4) -> 19.307935 | AR4: ='P101'!$AP4+'P101'!$AQ4 -> 39.357935
A5: jojoalva@espol.edu.ec | B5: 202314845 | C5: ALVAREZ CORDOVA JOSHUA JOEL | D5: 1 | F5: 0.5 | G5: 0.5 | H5: 0.5 | I5: 0 | J5: 1.25 | K5: 0 | L5: =SUM('P101'!$I5:$K5) -> 1.25 | M5: 0 | N5: 0 | O5: 0 | P5: =SUM('P101'!$M5:$O5) -> 0 | Q5: 0 | R5: 1.75 | S5: 0 | T5: =SUM('P101'!$Q5:$S5) -> 1.75 | U5: =('P101'!$L5+'P101'!$P5+'P101'!$T5)*'P101'!$F5 -> 1.5 | V5: 4.65 | W5: 0 | X5: =SUM('P101'!$V5:$W5)*'P101'!$G5 -> 2.325 | Y5: 0 | Z5: 0 | AA5: 0 | AB5: =IF(SUM('P101'!$Y5:$AA5)>5.9,"SI","NO") -> NO | AC5: =SUM('P101'!$Y5:$AA5) -> 0 | AD5: 1.5 | AE5: 5.5 | AF5: =IF('P101'!$AG5>5.9,"SI","NO") -> SI | AG5: =SUM('P101'!$AD5:$AE5) -> 7 | AH5: 4 | AI5: 5 | AJ5: =AVERAGE('P101'!$AH5:$AI5)*'P101'!$H5 -> 2.25 | AK5: 0 | AL5: 0 | AM5: 0 | AN5: =(('P101'!$AL5+'P101'!$AM5))*'P101'!$AK5 -> 0 | AO5: 9.75 | AP5: =SUM('P101'!$U5) -> 1.5 | AQ5: =SUM(AN5,AJ5,AG5,AC5,X5,'P101'!$AO5) -> 21.325 | AR5: ='P101'!$AP5+'P101'!$AQ5 -> 22.825
A6: joseanda@espol.edu.ec | B6: 202505103 | C6: ANDALUZ CARRASCO JOSE ISAIAS | D6: 3 | F6: 1.0042373 | G6: 1.0081542 | H6: 0.99477803 | I6: 2.25 | J6: 1 | K6: 4.1 | L6: =SUM('P101'!$I6:$K6) -> 7.35 | M6: 3 | N6: 2 | O6: 5 | P6: =SUM('P101'!$M6:$O6) -> 10 | Q6: 1.5 | R6: 2 | S6: 0 | T6: =SUM('P101'!$Q6:$S6) -> 3.5 | U6: =('P101'!$L6+'P101'!$P6+'P101'!$T6)*'P101'!$F6 -> 20.938348 | V6: 3.25 | W6: 5.2 | X6: =SUM('P101'!$V6:$W6)*'P101'!$G6 -> 8.5189032 | Y6: 1.5 | Z6: 0 | AA6: 0 | AB6: =IF(SUM('P101'!$Y6:$AA6)>5.9,"SI","NO") -> NO | AC6: =SUM('P101'!$Y6:$AA6) -> 1.5 | AD6: 1 | AE6: 5.25 | AF6: =IF('P101'!$AG6>5.9,"SI","NO") -> SI | AG6: =SUM('P101'!$AD6:$AE6) -> 6.25 | AH6: 4.5 | AI6: 5 | AJ6: =AVERAGE('P101'!$AH6:$AI6)*'P101'!$H6 -> 4.7251957 | AK6: 0 | AL6: 0 | AM6: 0 | AN6: =(('P101'!$AL6+'P101'!$AM6))*'P101'!$AK6 -> 0 | AO6: 7.5 | AP6: =SUM('P101'!$U6) -> 20.938348 | AQ6: =SUM(AN6,AJ6,AG6,AC6,X6,'P101'!$AO6) -> 28.494099 | AR6: ='P101'!$AP6+'P101'!$AQ6 -> 49.432447
A7: narboled@espol.edu.ec | B7: 202215091 | C7: ARBOLEDA ORDEÃ‘ANA NESTOR EZEQUIEL | D7: 1 | F7: 0.5 | G7: 1.069045 | H7: 0.5 | I7: 3 | J7: 1.25 | K7: 0 | L7: =SUM('P101'!$I7:$K7) -> 4.25 | M7: 0 | N7: 0 | O7: 0 | P7: =SUM('P101'!$M7:$O7) -> 0 | Q7: 0 | R7: 1.75 | S7: 0 | T7: =SUM('P101'!$Q7:$S7) -> 1.75 | U7: =('P101'!$L7+'P101'!$P7+'P101'!$T7)*'P101'!$F7 -> 3 | V7: 4.65 | W7: 6.8 | X7: =SUM('P101'!$V7:$W7)*'P101'!$G7 -> 12.240565 | Y7: 2 | Z7: 0 | AA7: 0 | AB7: =IF(SUM('P101'!$Y7:$AA7)>5.9,"SI","NO") -> NO | AC7: =SUM('P101'!$Y7:$AA7) -> 2 | AD7: 1.5 | AE7: 5.5 | AF7: =IF('P101'!$AG7>5.9,"SI","NO") -> SI | AG7: =SUM('P101'!$AD7:$AE7) -> 7 | AH7: 4 | AI7: 5 | AJ7: =AVERAGE('P101'!$AH7:$AI7)*'P101'!$H7 -> 2.25 | AK7: 0 | AL7: 0 | AM7: 0 | AN7: =(('P101'!$AL7+'P101'!$AM7))*'P101'!$AK7 -> 0 | AO7: 9.75 | AP7: =SUM('P101'!$U7) -> 3 | AQ7: =SUM(AN7,AJ7,AG7,AC7,X7,'P101'!$AO7) -> 33.240565 | AR7: ='P101'!$AP7+'P101'!$AQ7 -> 36.240565
A8: albearev@espol.edu.ec | B8: 202415923 | C8: AREVALO RODRIGUEZ CARLOS ALBERTO | D8: 9 | F8: 0.98428634 | G8: 1.0563983 | H8: 0.5 | I8: 1.5 | J8: 0 | K8: 0 | L8: =SUM('P101'!$I8:$K8) -> 1.5 | M8: 3 | N8: 2 | O8: 5 | P8: =SUM('P101'!$M8:$O8) -> 10 | Q8: 1.5 | R8: 1.5 | S8: 0 | T8: =SUM('P101'!$Q8:$S8) -> 3 | U8: =('P101'!$L8+'P101'!$P8+'P101'!$T8)*'P101'!$F8 -> 14.272152 | V8: 4.55 | W8: 3.1 | X8: =SUM('P101'!$V8:$W8)*'P101'!$G8 -> 8.0814467 | Y8: 1.5 | Z8: 0 | AA8: 3.75 | AB8: =IF(SUM('P101'!$Y8:$AA8)>5.9,"SI","NO") -> NO | AC8: =SUM('P101'!$Y8:$AA8) -> 5.25 | AD8: 1 | AE8: 5 | AF8: =IF('P101'!$AG8>5.9,"SI","NO") -> SI | AG8: =SUM('P101'!$AD8:$AE8) -> 6 | AH8: 0 | AI8: 0 | AJ8: =AVERAGE('P101'!$AH8:$AI8)*'P101'!$H8 -> 0 | AK8: 0 | AL8: 0 | AM8: 0 | AN8: =(('P101'!$AL8+'P101'!$AM8))*'P101'!$AK8 -> 0 | AO8: 5.5 | AP8: =SUM('P101'!$U8) -> 14.272152 | AQ8: =SUM(AN8,AJ8,AG8,AC8,X8,'P101'!$AO8) -> 24.831447 | AR8: ='P101'!$AP8+'P101'!$AQ8 -> 39.103599
A9: jelubaca@espol.edu.ec | B9: 202308474 | C9: BACA MENOSCAL JEAN LUIS | D9: 2 | F9: 1 | G9: 1 | H9: 0.99662731 | I9: 2.25 | J9: 1.75 | K9: 4.65 | L9: =SUM('P101'!$I9:$K9) -> 8.65 | M9: 3 | N9: 2 | O9: 5 | P9: =SUM('P101'!$M9:$O9) -> 10 | Q9: 2.25 | R9: 1.75 | S9: 4.45 | T9: =SUM('P101'!$Q9:$S9) -> 8.45 | U9: =('P101'!$L9+'P101'!$P9+'P101'!$T9)*'P101'!$F9 -> 27.1 | V9: 5 | W9: 6.8 | X9: =SUM('P101'!$V9:$W9)*'P101'!$G9 -> 11.8 | Y9: 1 | Z9: 1.5 | AA9: 5 | AB9: =IF(SUM('P101'!$Y9:$AA9)>5.9,"SI","NO") -> SI | AC9: =SUM('P101'!$Y9:$AA9) -> 7.5 | AD9: 2 | AE9: 4.25 | AF9: =IF('P101'!$AG9>5.9,"SI","NO") -> SI | AG9: =SUM('P101'!$AD9:$AE9) -> 6.25 | AH9: 5 | AI9: 3.5 | AJ9: =AVERAGE('P101'!$AH9:$AI9)*'P101'!$H9 -> 4.2356661 | AK9: 1 | AL9: 9 | AM9: 4 | AN9: =(('P101'!$AL9+'P101'!$AM9))*'P101'!$AK9 -> 13 | AO9: 8 | AP9: =SUM('P101'!$U9) -> 27.1 | AQ9: =SUM(AN9,AJ9,AG9,AC9,X9,'P101'!$AO9) -> 50.785666 | AR9: ='P101'!$AP9+'P101'!$AQ9 -> 77.885666
A10: jpbaca@espol.edu.ec | B10: 202311577 | C10: BACA MENOSCAL JEAN PIERE | D10: 6 | F10: 1 | G10: 0.5 | H10: 0.97547788 | I10: 3 | J10: 1.25 | K10: 3.95 | L10: =SUM('P101'!$I10:$K10) -> 8.2 | M10: 3 | N10: 2 | O10: 5 | P10: =SUM('P101'!$M10:$O10) -> 10 | Q10: 2.25 | R10: 1.75 | S10: 3.95 | T10: =SUM('P101'!$Q10:$S10) -> 7.95 | U10: =('P101'!$L10+'P101'!$P10+'P101'!$T10)*'P101'!$F10 -> 26.15 | V10: 4.9 | W10: 8.6 | X10: =SUM('P101'!$V10:$W10)*'P101'!$G10 -> 6.75 | Y10: 1.5 | Z10: 3 | AA10: 2.5 | AB10: =IF(SUM('P101'!$Y10:$AA10)>5.9,"SI","NO") -> SI | AC10: =SUM('P101'!$Y10:$AA10) -> 7 | AD10: 1.75 | AE10: 6 | AF10: =IF('P101'!$AG10>5.9,"SI","NO") -> SI | AG10: =SUM('P101'!$AD10:$AE10) -> 7.75 | AH10: 5 | AI10: 4.5 | AJ10: =AVERAGE('P101'!$AH10:$AI10)*'P101'!$H10 -> 4.6335199 | AK10: 1 | AL10: 1 | AM10: 7 | AN10: =(('P101'!$AL10+'P101'!$AM10))*'P101'!$AK10 -> 8 | AO10: 10 | AP10: =SUM('P101'!$U10) -> 26.15 | AQ10: =SUM(AN10,AJ10,AG10,AC10,X10,'P101'!$AO10) -> 44.13352 | AR10: ='P101'!$AP10+'P101'!$AQ10 -> 70.28352
A11: jubecerr@espol.edu.ec | B11: 202508875 | C11: BECERRA POZO JULIO CESAR | D11: 2 | F11: 1 | G11: 1 | H11: 1.0050378 | I11: 1.5 | J11: 0 | K11: 0 | L11: =SUM('P101'!$I11:$K11) -> 1.5 | M11: 3 | N11: 2 | O11: 5 | P11: =SUM('P101'!$M11:$O11) -> 10 | Q11: 2.25 | R11: 1.75 | S11: 4.45 | T11: =SUM('P101'!$Q11:$S11) -> 8.45 | U11: =('P101'!$L11+'P101'!$P11+'P101'!$T11)*'P101'!$F11 -> 19.95 | V11: 5 | W11: 6.8 | X11: =SUM('P101'!$V11:$W11)*'P101'!$G11 -> 11.8 | Y11: 1 | Z11: 3 | AA11: 3.75 | AB11: =IF(SUM('P101'!$Y11:$AA11)>5.9,"SI","NO") -> SI | AC11: =SUM('P101'!$Y11:$AA11) -> 7.75 | AD11: 2 | AE11: 4.25 | AF11: =IF('P101'!$AG11>5.9,"SI","NO") -> SI | AG11: =SUM('P101'!$AD11:$AE11) -> 6.25 | AH11: 5 | AI11: 3.5 | AJ11: =AVERAGE('P101'!$AH11:$AI11)*'P101'!$H11 -> 4.2714107 | AK11: 1 | AL11: 8.5 | AM11: 6 | AN11: =(('P101'!$AL11+'P101'!$AM11))*'P101'!$AK11 -> 14.5 | AO11: 8 | AP11: =SUM('P101'!$U11) -> 19.95 | AQ11: =SUM(AN11,AJ11,AG11,AC11,X11,'P101'!$AO11) -> 52.571411 | AR11: ='P101'!$AP11+'P101'!$AQ11 -> 72.521411
A12: micarpio@espol.edu.ec | B12: 202400610 | C12: CARPIO NARVAEZ MIGUEL BENJAMIN | D12: 3 | F12: 1.0042373 | G12: 0.5 | H12: 1.0206207 | I12: 3 | J12: 1 | K12: 4.1 | L12: =SUM('P101'!$I12:$K12) -> 8.1 | M12: 3 | N12: 2 | O12: 5 | P12: =SUM('P101'!$M12:$O12) -> 10 | Q12: 2.25 | R12: 2 | S12: 4.7 | T12: =SUM('P101'!$Q12:$S12) -> 8.95 | U12: =('P101'!$L12+'P101'!$P12+'P101'!$T12)*'P101'!$F12 -> 27.164619 | V12: 3.25 | W12: 5.2 | X12: =SUM('P101'!$V12:$W12)*'P101'!$G12 -> 4.225 | Y12: 2 | Z12: 3 | AA12: 3.75 | AB12: =IF(SUM('P101'!$Y12:$AA12)>5.9,"SI","NO") -> SI | AC12: =SUM('P101'!$Y12:$AA12) -> 8.75 | AD12: 1 | AE12: 5.25 | AF12: =IF('P101'!$AG12>5.9,"SI","NO") -> SI | AG12: =SUM('P101'!$AD12:$AE12) -> 6.25 | AH12: 4.5 | AI12: 5 | AJ12: =AVERAGE('P101'!$AH12:$AI12)*'P101'!$H12 -> 4.8479484 | AK12: 1 | AL12: 7.5 | AM12: 5.5 | AN12: =(('P101'!$AL12+'P101'!$AM12))*'P101'!$AK12 -> 13 | AO12: 7.5 | AP12: =SUM('P101'!$U12) -> 27.164619 | AQ12: =SUM(AN12,AJ12,AG12,AC12,X12,'P101'!$AO12) -> 44.572948 | AR12: ='P101'!$AP12+'P101'!$AQ12 -> 71.737568
A13: adjacast@espol.edu.ec | B13: 202310579 | C13: CASTRO MONTIEL ADRIANA JAMILET | D13: 4 | F13: 0.96395204 | G13: 0.99890291 | H13: 1.0088891 | I13: 2.25 | J13: 0.75 | K13: 4.9 | L13: =SUM('P101'!$I13:$K13) -> 7.9 | M13: 3 | N13: 2 | O13: 5 | P13: =SUM('P101'!$M13:$O13) -> 10 | Q13: 2.25 | R13: 2 | S13: 5 | T13: =SUM('P101'!$Q13:$S13) -> 9.25 | U13: =('P101'!$L13+'P101'!$P13+'P101'!$T13)*'P101'!$F13 -> 26.171298 | V13: 4.6 | W13: 8.3 | X13: =SUM('P101'!$V13:$W13)*'P101'!$G13 -> 12.885848 | Y13: 1.5 | Z13: 2 | AA13: 3 | AB13: =IF(SUM('P101'!$Y13:$AA13)>5.9,"SI","NO") -> SI | AC13: =SUM('P101'!$Y13:$AA13) -> 6.5 | AD13: 2 | AE13: 4 | AF13: =IF('P101'!$AG13>5.9,"SI","NO") -> SI | AG13: =SUM('P101'!$AD13:$AE13) -> 6 | AH13: 4.5 | AI13: 4.5 | AJ13: =AVERAGE('P101'!$AH13:$AI13)*'P101'!$H13 -> 4.5400008 | AK13: 1 | AL13: 7.5 | AM13: 7.5 | AN13: =(('P101'!$AL13+'P101'!$AM13))*'P101'!$AK13 -> 15 | AO13: 10 | AP13: =SUM('P101'!$U13) -> 26.171298 | AQ13: =SUM(AN13,AJ13,AG13,AC13,X13,'P101'!$AO13) -> 54.925848 | AR13: ='P101'!$AP13+'P101'!$AQ13 -> 81.097146
A14: wilsdiaz@espol.edu.ec | B14: 202508982 | C14: DIAZ MONTERO WILSON SEBASTIAN | D14: 10 | F14: 1 | G14: 1 | H14: 1 | I14: 2.25 | J14: 2 | K14: 4.7 | L14: =SUM('P101'!$I14:$K14) -> 8.95 | M14: 3 | N14: 2 | O14: 5 | P14: =SUM('P101'!$M14:$O14) -> 10 | Q14: 1.5 | R14: 2 | S14: 0 | T14: =SUM('P101'!$Q14:$S14) -> 3.5 | U14: =('P101'!$L14+'P101'!$P14+'P101'!$T14)*'P101'!$F14 -> 22.45 | V14: 4.05 | W14: 6 | X14: =SUM('P101'!$V14:$W14)*'P101'!$G14 -> 10.05 | Y14: 1.5 | Z14: 1.5 | AA14: 0 | AB14: =IF(SUM('P101'!$Y14:$AA14)>5.9,"SI","NO") -> NO | AC14: =SUM('P101'!$Y14:$AA14) -> 3 | AD14: 1.5 | AE14: 5 | AF14: =IF('P101'!$AG14>5.9,"SI","NO") -> SI | AG14: =SUM('P101'!$AD14:$AE14) -> 6.5 | AH14: 0 | AI14: 0 | AJ14: =AVERAGE('P101'!$AH14:$AI14)*'P101'!$H14 -> 0 | AK14: 0 | AL14: 0 | AM14: 0 | AN14: =(('P101'!$AL14+'P101'!$AM14))*'P101'!$AK14 -> 0 | AO14: 8.5 | AP14: =SUM('P101'!$U14) -> 22.45 | AQ14: =SUM(AN14,AJ14,AG14,AC14,X14,'P101'!$AO14) -> 28.05 | AR14: ='P101'!$AP14+'P101'!$AQ14 -> 50.5
A15: davfuert@espol.edu.ec | B15: 202408043 | C15: FUERTES CHALEN DAVID ALEXANDER | D15: 2 | F15: 1 | G15: 1 | H15: 0.99662731 | I15: 3 | J15: 1.75 | K15: 0 | L15: =SUM('P101'!$I15:$K15) -> 4.75 | M15: 0 | N15: 0 | O15: 0 | P15: =SUM('P101'!$M15:$O15) -> 0 | Q15: 1 | R15: 1.75 | S15: 0 | T15: =SUM('P101'!$Q15:$S15) -> 2.75 | U15: =('P101'!$L15+'P101'!$P15+'P101'!$T15)*'P101'!$F15 -> 7.5 | V15: 5 | W15: 6.8 | X15: =SUM('P101'!$V15:$W15)*'P101'!$G15 -> 11.8 | Y15: 0.5 | Z15: 1.5 | AA15: 0 | AB15: =IF(SUM('P101'!$Y15:$AA15)>5.9,"SI","NO") -> NO | AC15: =SUM('P101'!$Y15:$AA15) -> 2 | AD15: 2 | AE15: 4.25 | AF15: =IF('P101'!$AG15>5.9,"SI","NO") -> SI | AG15: =SUM('P101'!$AD15:$AE15) -> 6.25 | AH15: 5 | AI15: 3.5 | AJ15: =AVERAGE('P101'!$AH15:$AI15)*'P101'!$H15 -> 4.2356661 | AK15: 0 | AL15: 0 | AM15: 0 | AN15: =(('P101'!$AL15+'P101'!$AM15))*'P101'!$AK15 -> 0 | AO15: 8 | AP15: =SUM('P101'!$U15) -> 7.5 | AQ15: =SUM(AN15,AJ15,AG15,AC15,X15,'P101'!$AO15) -> 32.285666 | AR15: ='P101'!$AP15+'P101'!$AQ15 -> 39.785666
... A18: jusgomez@espol.edu.ec | B18: 202411674 | C18: GOMEZ TACURI JUSTINE IBETH | D18: 8 | F18: 1.0248552 | G18: 1.0044944 | H18: 0.99477803 | I18: 1.5 | J18: 0 | K18: 0 | L18: =SUM('P101'!$I18:$K18) -> 1.5 | M18: 3 | N18: 2 | O18: 5 | P18: =SUM('P101'!$M18:$O18) -> 10 | Q18: 1.5 | R18: 2 | S18: 0 | T18: =SUM('P101'!$Q18:$S18) -> 3.5 | U18: =('P101'!$L18+'P101'!$P18+'P101'!$T18)*'P101'!$F18 -> 15.372828 | V18: 4.4 | W18: 7.3 | X18: =SUM('P101'!$V18:$W18)*'P101'!$G18 -> 11.752585 | Y18: 2 | Z18: 3 | AA18: 1.25 | AB18: =IF(SUM('P101'!$Y18:$AA18)>5.9,"SI","NO") -> SI | AC18: =SUM('P101'!$Y18:$AA18) -> 6.25 | AD18: 2 | AE18: 4 | AF18: =IF('P101'!$AG18>5.9,"SI","NO") -> SI | AG18: =SUM('P101'!$AD18:$AE18) -> 6 | AH18: 4 | AI18: 5 | AJ18: =AVERAGE('P101'!$AH18:$AI18)*'P101'!$H18 -> 4.4765011 | AK18: 1 | AL18: 5 | AM18: 6 | AN18: =(('P101'!$AL18+'P101'!$AM18))*'P101'!$AK18 -> 11 | AO18: 9.5 | AP18: =SUM('P101'!$U18) -> 15.372828 | AQ18: =SUM(AN18,AJ18,AG18,AC18,X18,'P101'!$AO18) -> 48.979086 | AR18: ='P101'!$AP18+'P101'!$AQ18 -> 64.351914
A19: angoestr@espol.edu.ec | B19: 202307872 | C19: GORDILLO ESTRADA ANGIE SOLANGE | D19: 5 | F19: 1.0010015 | G19: 1 | H19: 1.0025306 | I19: 0.75 | J19: 0 | K19: 0 | L19: =SUM('P101'!$I19:$K19) -> 0.75 | M19: 3 | N19: 2 | O19: 5 | P19: =SUM('P101'!$M19:$O19) -> 10 | Q19: 3 | R19: 1.75 | S19: 4.8 | T19: =SUM('P101'!$Q19:$S19) -> 9.55 | U19: =('P101'!$L19+'P101'!$P19+'P101'!$T19)*'P101'!$F19 -> 20.320331 | V19: 4.55 | W19: 6.4 | X19: =SUM('P101'!$V19:$W19)*'P101'!$G19 -> 10.95 | Y19: 1 | Z19: 1 | AA19: 4 | AB19: =IF(SUM('P101'!$Y19:$AA19)>5.9,"SI","NO") -> SI | AC19: =SUM('P101'!$Y19:$AA19) -> 6 | AD19: 1.5 | AE19: 7 | AF19: =IF('P101'!$AG19>5.9,"SI","NO") -> SI | AG19: =SUM('P101'!$AD19:$AE19) -> 8.5 | AH19: 3 | AI19: 4.5 | AJ19: =AVERAGE('P101'!$AH19:$AI19)*'P101'!$H19 -> 3.7594897 | AK19: 1 | AL19: 5 | AM19: 9 | AN19: =(('P101'!$AL19+'P101'!$AM19))*'P101'!$AK19 -> 14 | AO19: 10 | AP19: =SUM('P101'!$U19) -> 20.320331 | AQ19: =SUM(AN19,AJ19,AG19,AC19,X19,'P101'!$AO19) -> 53.20949 | AR19: 94
A20: silvguam@espol.edu.ec | B20: 202503249 | C20: GUAMAN CEDEÃ‘O SILVIA LISSETTE | D20: 4 | F20: 1.0305081 | G20: 1.1470787 | H20: 1.0350983 | I20: 3 | J20: 0.75 | K20: 4.9 | L20: =SUM('P101'!$I20:$K20) -> 8.65 | M20: 3 | N20: 2 | O20: 5 | P20: =SUM('P101'!$M20:$O20) -> 10 | Q20: 1.5 | R20: 2 | S20: 0 | T20: =SUM('P101'!$Q20:$S20) -> 3.5 | U20: =('P101'!$L20+'P101'!$P20+'P101'!$T20)*'P101'!$F20 -> 22.825754 | V20: 4.6 | W20: 8.3 | X20: =SUM('P101'!$V20:$W20)*'P101'!$G20 -> 14.797315 | Y20: 2 | Z20: 1.5 | AA20: 1.25 | AB20: =IF(SUM('P101'!$Y20:$AA20)>5.9,"SI","NO") -> NO | AC20: =SUM('P101'!$Y20:$AA20) -> 4.75 | AD20: 2 | AE20: 4 | AF20: =IF('P101'!$AG20>5.9,"SI","NO") -> SI | AG20: =SUM('P101'!$AD20:$AE20) -> 6 | AH20: 4.5 | AI20: 4.5 | AJ20: =AVERAGE('P101'!$AH20:$AI20)*'P101'!$H20 -> 4.6579425 | AK20: 1 | AL20: 0 | AM20: 0 | AN20: =(('P101'!$AL20+'P101'!$AM20))*'P101'!$AK20 -> 0 | AO20: 10 | AP20: =SUM('P101'!$U20) -> 22.825754 | AQ20: =SUM(AN20,AJ20,AG20,AC20,X20,'P101'!$AO20) -> 40.205257 | AR20: ='P101'!$AP20+'P101'!$AQ20 -> 63.031011
A21: alexhelg@espol.edu.ec | B21: 202403002 | C21: HELGUERO VILLON ALEXIS MARCOS | D21: 7 | F21: 1 | G21: 0.97958969 | H21: 0.5 | I21: 3 | J21: 0.75 | K21: 3.55 | L21: =SUM('P101'!$I21:$K21) -> 7.3 | M21: 0 | N21: 0 | O21: 0 | P21: =SUM('P101'!$M21:$O21) -> 0 | Q21: 1.13 | R21: 1.25 | S21: 0 | T21: =SUM('P101'!$Q21:$S21) -> 2.38 | U21: =('P101'!$L21+'P101'!$P21+'P101'!$T21)*'P101'!$F21 -> 9.68 | V21: 4.2 | W21: 7.3 | X21: =SUM('P101'!$V21:$W21)*'P101'!$G21 -> 11.265281 | Y21: 1.5 | Z21: 0 | AA21: 0 | AB21: =IF(SUM('P101'!$Y21:$AA21)>5.9,"SI","NO") -> NO | AC21: =SUM('P101'!$Y21:$AA21) -> 1.5 | AD21: 1.5 | AE21: 0 | AF21: =IF('P101'!$AG21>5.9,"SI","NO") -> NO | AG21: =SUM('P101'!$AD21:$AE21) -> 1.5 | AH21: 0 | AI21: 0 | AJ21: =AVERAGE('P101'!$AH21:$AI21)*'P101'!$H21 -> 0 | AK21: 0 | AL21: 0 | AM21: 0 | AN21: =(('P101'!$AL21+'P101'!$AM21))*'P101'!$AK21 -> 0 | AO21: 0 | AP21: =SUM('P101'!$U21) -> 9.68 | AQ21: =SUM(AN21,AJ21,AG21,AC21,X21,'P101'!$AO21) -> 14.265281 | AR21: ='P101'!$AP21+'P101'!$AQ21 -> 23.945281
A22: edhernan@espol.edu.ec | B22: 202508842 | C22: HERNANDEZ TRIVIÃ‘O EDWIN JAVIER | D22: 2 | F22: 1 | G22: 0.5 | H22: 1.0050378 | I22: 2.25 | J22: 1.75 | K22: 4.65 | L22: =SUM('P101'!$I22:$K22) -> 8.65 | M22: 3 | N22: 2 | O22: 5 | P22: =SUM('P101'!$M22:$O22) -> 10 | Q22: 2.25 | R22: 1.75 | S22: 4.45 | T22: =SUM('P101'!$Q22:$S22) -> 8.45 | U22: =('P101'!$L22+'P101'!$P22+'P101'!$T22)*'P101'!$F22 -> 27.1 | V22: 5 | W22: 6.8 | X22: =SUM('P101'!$V22:$W22)*'P101'!$G22 -> 5.9 | Y22: 0.5 | Z22: 1.5 | AA22: 4 | AB22: =IF(SUM('P101'!$Y22:$AA22)>5.9,"SI","NO") -> SI | AC22: =SUM('P101'!$Y22:$AA22) -> 6 | AD22: 2 | AE22: 4.25 | AF22: =IF('P101'!$AG22>5.9,"SI","NO") -> SI | AG22: =SUM('P101'!$AD22:$AE22) -> 6.25 | AH22: 5 | AI22: 3.5 | AJ22: =AVERAGE('P101'!$AH22:$AI22)*'P101'!$H22 -> 4.2714107 | AK22: 1 | AL22: 9 | AM22: 6 | AN22: =(('P101'!$AL22+'P101'!$AM22))*'P101'!$AK22 -> 15 | AO22: 8 | AP22: =SUM('P101'!$U22) -> 27.1 | AQ22: =SUM(AN22,AJ22,AG22,AC22,X22,'P101'!$AO22) -> 45.421411 | AR22: ='P101'!$AP22+'P101'!$AQ22 -> 72.521411
A23: jelarena@espol.edu.ec | B23: 202509030 | C23: LARENA ALCIVAR JEANPOUL ALEXANDER | D23: 1 | F23: 1.1521431 | G23: 1.069045 | H23: 1.2015028 | I23: 3 | J23: 1.25 | K23: 5 | L23: =SUM('P101'!$I23:$K23) -> 9.25 | M23: 3 | N23: 2 | O23: 5 | P23: =SUM('P101'!$M23:$O23) -> 10 | Q23: 0.5 | R23: 1.75 | S23: 0 | T23: =SUM('P101'!$Q23:$S23) -> 2.25 | U23: =('P101'!$L23+'P101'!$P23+'P101'!$T23)*'P101'!$F23 -> 24.771076 | V23: 4.65 | W23: 6.8 | X23: =SUM('P101'!$V23:$W23)*'P101'!$G23 -> 12.240565 | Y23: 1.5 | Z23: 3 | AA23: 3.75 | AB23: =IF(SUM('P101'!$Y23:$AA23)>5.9,"SI","NO") -> SI | AC23: =SUM('P101'!$Y23:$AA23) -> 8.25 | AD23: 1.5 | AE23: 5.5 | AF23: =IF('P101'!$AG23>5.9,"SI","NO") -> SI | AG23: =SUM('P101'!$AD23:$AE23) -> 7 | AH23: 4 | AI23: 5 | AJ23: =AVERAGE('P101'!$AH23:$AI23)*'P101'!$H23 -> 5.4067627 | AK23: 1 | AL23: 6 | AM23: 10 | AN23: =(('P101'!$AL23+'P101'!$AM23))*'P101'!$AK23 -> 16 | AO23: 9.75 | AP23: =SUM('P101'!$U23) -> 24.771076 | AQ23: =SUM(AN23,AJ23,AG23,AC23,X23,'P101'!$AO23) -> 58.647328 | AR23: ='P101'!$AP23+'P101'!$AQ23 -> 83.418403
A24: krisleon@espol.edu.ec | B24: 202410155 | C24: LEON VELIZ KRISTHEL BRIGGITTE | D24: 8 | F24: 1.0459885 | G24: 1.0397505 | H24: 1.0206207 | I24: 3 | J24: 1.25 | K24: 2.1 | L24: =SUM('P101'!$I24:$K24) -> 6.35 | M24: 3 | N24: 2 | O24: 5 | P24: =SUM('P101'!$M24:$O24) -> 10 | Q24: 1.5 | R24: 2 | S24: 0 | T24: =SUM('P101'!$Q24:$S24) -> 3.5 | U24: =('P101'!$L24+'P101'!$P24+'P101'!$T24)*'P101'!$F24 -> 20.762871 | V24: 4.4 | W24: 7.3 | X24: =SUM('P101'!$V24:$W24)*'P101'!$G24 -> 12.165081 | Y24: 1.5 | Z24: 1 | AA24: 3.5 | AB24: =IF(SUM('P101'!$Y24:$AA24)>5.9,"SI","NO") -> SI | AC24: =SUM('P101'!$Y24:$AA24) -> 6 | AD24: 2 | AE24: 4 | AF24: =IF('P101'!$AG24>5.9,"SI","NO") -> SI | AG24: =SUM('P101'!$AD24:$AE24) -> 6 | AH24: 4 | AI24: 5 | AJ24: =AVERAGE('P101'!$AH24:$AI24)*'P101'!$H24 -> 4.5927933 | AK24: 1 | AL24: 8 | AM24: 7 | AN24: =(('P101'!$AL24+'P101'!$AM24))*'P101'!$AK24 -> 15 | AO24: 9.5 | AP24: =SUM('P101'!$U24) -> 20.762871 | AQ24: =SUM(AN24,AJ24,AG24,AC24,X24,'P101'!$AO24) -> 53.257874 | AR24: ='P101'!$AP24+'P101'!$AQ24 -> 74.020745
A25: xiolitar@espol.edu.ec | B25: 202505939 | C25: LITARDO MEDINA XIOMARA MISHELLE | D25: 3 | F25: 0.99893787 | G25: 1.0081542 | H25: 0.99477803 | I25: 3 | J25: 1 | K25: 4.1 | L25: =SUM('P101'!$I25:$K25) -> 8.1 | M25: 3 | N25: 2 | O25: 5 | P25: =SUM('P101'!$M25:$O25) -> 10 | Q25: 1.5 | R25: 2 | S25: 0 | T25: =SUM('P101'!$Q25:$S25) -> 3.5 | U25: =('P101'!$L25+'P101'!$P25+'P101'!$T25)*'P101'!$F25 -> 21.577058 | V25: 3.25 | W25: 5.2 | X25: =SUM('P101'!$V25:$W25)*'P101'!$G25 -> 8.5189032 | Y25: 1.5 | Z25: 0 | AA25: 2.5 | AB25: =IF(SUM('P101'!$Y25:$AA25)>5.9,"SI","NO") -> NO | AC25: =SUM('P101'!$Y25:$AA25) -> 4 | AD25: 1 | AE25: 5.25 | AF25: =IF('P101'!$AG25>5.9,"SI","NO") -> SI | AG25: =SUM('P101'!$AD25:$AE25) -> 6.25 | AH25: 4.5 | AI25: 5 | AJ25: =AVERAGE('P101'!$AH25:$AI25)*'P101'!$H25 -> 4.7251957 | AK25: 0 | AL25: 0 | AM25: 0 | AN25: =(('P101'!$AL25+'P101'!$AM25))*'P101'!$AK25 -> 0 | AO25: 7.5 | AP25: =SUM('P101'!$U25) -> 21.577058 | AQ25: =SUM(AN25,AJ25,AG25,AC25,X25,'P101'!$AO25) -> 30.994099 | AR25: ='P101'!$AP25+'P101'!$AQ25 -> 52.571157
A26: irwiluci@espol.edu.ec | B26: 202510350 | C26: LUCIN MUÃ‘IZ IRWIN AARON | D26: 7 | F26: 1 | G26: 1.0050378 | H26: 0.96768599 | I26: 3 | J26: 0.75 | K26: 3.55 | L26: =SUM('P101'!$I26:$K26) -> 7.3 | M26: 3 | N26: 2 | O26: 5 | P26: =SUM('P101'!$M26:$O26) -> 10 | Q26: 0 | R26: 1.25 | S26: 0 | T26: =SUM('P101'!$Q26:$S26) -> 1.25 | U26: =('P101'!$L26+'P101'!$P26+'P101'!$T26)*'P101'!$F26 -> 18.55 | V26: 4.2 | W26: 7.3 | X26: =SUM('P101'!$V26:$W26)*'P101'!$G26 -> 11.557935 | Y26: 1.5 | Z26: 1.5 | AA26: 3.75 | AB26: =IF(SUM('P101'!$Y26:$AA26)>5.9,"SI","NO") -> SI | AC26: =SUM('P101'!$Y26:$AA26) -> 6.75 | AD26: 1.5 | AE26: 0 | AF26: =IF('P101'!$AG26>5.9,"SI","NO") -> NO | AG26: =SUM('P101'!$AD26:$AE26) -> 1.5 | AH26: 0 | AI26: 0 | AJ26: =AVERAGE('P101'!$AH26:$AI26)*'P101'!$H26 -> 0 | AK26: 0 | AL26: 0 | AM26: 0 | AN26: =(('P101'!$AL26+'P101'!$AM26))*'P101'!$AK26 -> 0 | AO26: 0 | AP26: =SUM('P101'!$U26) -> 18.55 | AQ26: =SUM(AN26,AJ26,AG26,AC26,X26,'P101'!$AO26) -> 19.807935 | AR26: ='P101'!$AP26+'P101'!$AQ26 -> 38.357935
A27: rodmacas@espol.edu.ec | B27: 202501458 | C27: MACAS CABRERA RODRIGO STEPHAN | D27: 9 | F27: 0.989927 | G27: 1.0625224 | H27: 1.0073724 | I27: 2.25 | J27: 1.25 | K27: 4.15 | L27: =SUM('P101'!$I27:$K27) -> 7.65 | M27: 3 | N27: 2 | O27: 5 | P27: =SUM('P101'!$M27:$O27) -> 10 | Q27: 2 | R27: 1.5 | S27: 3.5 | T27: =SUM('P101'!$Q27:$S27) -> 7 | U27: =('P101'!$L27+'P101'!$P27+'P101'!$T27)*'P101'!$F27 -> 24.4017 | V27: 4.55 | W27: 3.1 | X27: =SUM('P101'!$V27:$W27)*'P101'!$G27 -> 8.1282961 | Y27: 1 | Z27: 0 | AA27: 1.25 | AB27: =IF(SUM('P101'!$Y27:$AA27)>5.9,"SI","NO") -> NO | AC27: =SUM('P101'!$Y27:$AA27) -> 2.25 | AD27: 1 | AE27: 5 | AF27: =IF('P101'!$AG27>5.9,"SI","NO") -> SI | AG27: =SUM('P101'!$AD27:$AE27) -> 6 | AH27: 0 | AI27: 0 | AJ27: =AVERAGE('P101'!$AH27:$AI27)*'P101'!$H27 -> 0 | AK27: 0 | AL27: 0 | AM27: 0 | AN27: =(('P101'!$AL27+'P101'!$AM27))*'P101'!$AK27 -> 0 | AO27: 5.5 | AP27: =SUM('P101'!$U27) -> 24.4017 | AQ27: =SUM(AN27,AJ27,AG27,AC27,X27,'P101'!$AO27) -> 21.878296 | AR27: ='P101'!$AP27+'P101'!$AQ27 -> 46.279997
A28: jogamanj@espol.edu.ec | B28: 202211207 | C28: MANJARRES MOLINA JOSE GABRIEL | D28: 6 | F28: 1 | G28: 1 | H28: 0.96656922 | I28: 2.25 | J28: 1.25 | K28: 3.95 | L28: =SUM('P101'!$I28:$K28) -> 7.45 | M28: 3 | N28: 2 | O28: 5 | P28: =SUM('P101'!$M28:$O28) -> 10 | Q28: 1.8 | R28: 1.75 | S28: 3.95 | T28: =SUM('P101'!$Q28:$S28) -> 7.5 | U28: =('P101'!$L28+'P101'!$P28+'P101'!$T28)*'P101'!$F28 -> 24.95 | V28: 4.9 | W28: 8.6 | X28: =SUM('P101'!$V28:$W28)*'P101'!$G28 -> 13.5 | Y28: 2 | Z28: 3 | AA28: 3.75 | AB28: =IF(SUM('P101'!$Y28:$AA28)>5.9,"SI","NO") -> SI | AC28: =SUM('P101'!$Y28:$AA28) -> 8.75 | AD28: 1.75 | AE28: 6 | AF28: =IF('P101'!$AG28>5.9,"SI","NO") -> SI | AG28: =SUM('P101'!$AD28:$AE28) -> 7.75 | AH28: 5 | AI28: 4.5 | AJ28: =AVERAGE('P101'!$AH28:$AI28)*'P101'!$H28 -> 4.5912038 | AK28: 1 | AL28: 2.5 | AM28: 7 | AN28: =(('P101'!$AL28+'P101'!$AM28))*'P101'!$AK28 -> 9.5 | AO28: 10 | AP28: =SUM('P101'!$U28) -> 24.95 | AQ28: =SUM(AN28,AJ28,AG28,AC28,X28,'P101'!$AO28) -> 54.091204 | AR28: ='P101'!$AP28+'P101'!$AQ28 -> 79.041204
A29: ivanmarc@espol.edu.ec | B29: 202318341 | C29: MARCILLO ALCIVAR IVAN JESUS | D29: 9 | F29: 0.99553569 | G29: 1.0060643 | H29: 1.0073724 | I29: 1.5 | J29: 0 | K29: 0 | L29: =SUM('P101'!$I29:$K29) -> 1.5 | M29: 3 | N29: 2 | O29: 5 | P29: =SUM('P101'!$M29:$O29) -> 10 | Q29: 1.63 | R29: 1.5 | S29: 0 | T29: =SUM('P101'!$Q29:$S29) -> 3.13 | U29: =('P101'!$L29+'P101'!$P29+'P101'!$T29)*'P101'!$F29 -> 14.564687 | V29: 4.55 | W29: 3.1 | X29: =SUM('P101'!$V29:$W29)*'P101'!$G29 -> 7.6963922 | Y29: 1.5 | Z29: 0 | AA29: 1.25 | AB29: =IF(SUM('P101'!$Y29:$AA29)>5.9,"SI","NO") -> NO | AC29: =SUM('P101'!$Y29:$AA29) -> 2.75 | AD29: 1 | AE29: 5 | AF29: =IF('P101'!$AG29>5.9,"SI","NO") -> SI | AG29: =SUM('P101'!$AD29:$AE29) -> 6 | AH29: 0 | AI29: 0 | AJ29: =AVERAGE('P101'!$AH29:$AI29)*'P101'!$H29 -> 0 | AK29: 0 | AL29: 0 | AM29: 0 | AN29: =(('P101'!$AL29+'P101'!$AM29))*'P101'!$AK29 -> 0 | AO29: 5.5 | AP29: =SUM('P101'!$U29) -> 14.564687 | AQ29: =SUM(AN29,AJ29,AG29,AC29,X29,'P101'!$AO29) -> 21.946392 | AR29: ='P101'!$AP29+'P101'!$AQ29 -> 36.511079
A30: rjmirand@espol.edu.ec | B30: 202300745 | C30: MIRANDA SANCHEZ REBECA JACQUELINE | D30: 5 | F30: 1.0010015 | G30: 1 | H30: 0.98124301 | I30: 2.25 | J30: 1.75 | K30: 4.1 | L30: =SUM('P101'!$I30:$K30) -> 8.1 | M30: 3 | N30: 2 | O30: 5 | P30: =SUM('P101'!$M30:$O30) -> 10 | Q30: 2 | R30: 1.75 | S30: 4.8 | T30: =SUM('P101'!$Q30:$S30) -> 8.55 | U30: =('P101'!$L30+'P101'!$P30+'P101'!$T30)*'P101'!$F30 -> 26.67669 | V30: 4.55 | W30: 6.4 | X30: =SUM('P101'!$V30:$W30)*'P101'!$G30 -> 10.95 | Y30: 1.5 | Z30: 0 | AA30: 4.5 | AB30: =IF(SUM('P101'!$Y30:$AA30)>5.9,"SI","NO") -> SI | AC30: =SUM('P101'!$Y30:$AA30) -> 6 | AD30: 1.5 | AE30: 7 | AF30: =IF('P101'!$AG30>5.9,"SI","NO") -> SI | AG30: =SUM('P101'!$AD30:$AE30) -> 8.5 | AH30: 3 | AI30: 4.5 | AJ30: =AVERAGE('P101'!$AH30:$AI30)*'P101'!$H30 -> 3.6796613 | AK30: 1 | AL30: 4 | AM30: 8.5 | AN30: =(('P101'!$AL30+'P101'!$AM30))*'P101'!$AK30 -> 12.5 | AO30: 10 | AP30: =SUM('P101'!$U30) -> 26.67669 | AQ30: =SUM(AN30,AJ30,AG30,AC30,X30,'P101'!$AO30) -> 51.629661 | AR30: 88
A31: susamora@espol.edu.ec | B31: 202510152 | C31: MORA LUGO SUSAN VALESKA | D31: 3 | F31: 0.99893787 | G31: 1.0081542 | H31: 0.99477803 | I31: 3 | J31: 1 | K31: 4.1 | L31: =SUM('P101'!$I31:$K31) -> 8.1 | M31: 3 | N31: 2 | O31: 5 | P31: =SUM('P101'!$M31:$O31) -> 10 | Q31: 1.5 | R31: 2 | S31: 0 | T31: =SUM('P101'!$Q31:$S31) -> 3.5 | U31: =('P101'!$L31+'P101'!$P31+'P101'!$T31)*'P101'!$F31 -> 21.577058 | V31: 3.25 | W31: 5.2 | X31: =SUM('P101'!$V31:$W31)*'P101'!$G31 -> 8.5189032 | Y31: 1.5 | Z31: 0 | AA31: 1.25 | AB31: =IF(SUM('P101'!$Y31:$AA31)>5.9,"SI","NO") -> NO | AC31: =SUM('P101'!$Y31:$AA31) -> 2.75 | AD31: 1 | AE31: 5.25 | AF31: =IF('P101'!$AG31>5.9,"SI","NO") -> SI | AG31: =SUM('P101'!$AD31:$AE31) -> 6.25 | AH31: 4.5 | AI31: 5 | AJ31: =AVERAGE('P101'!$AH31:$AI31)*'P101'!$H31 -> 4.7251957 | AK31: 0 | AL31: 0 | AM31: 0 | AN31: =(('P101'!$AL31+'P101'!$AM31))*'P101'!$AK31 -> 0 | AO31: 7.5 | AP31: =SUM('P101'!$U31) -> 21.577058 | AQ31: =SUM(AN31,AJ31,AG31,AC31,X31,'P101'!$AO31) -> 29.744099 | AR31: ='P101'!$AP31+'P101'!$AQ31 -> 51.321157
A32: gnordone@espol.edu.ec | B32: 202315552 | C32: ORDOÃ‘EZ OLLAGUE GENESIS NICOLE | D32: 4 | F32: 0.96395204 | G32: 1.0523574 | H32: 0.5 | I32: 3 | J32: 0.75 | K32: 4.9 | L32: =SUM('P101'!$I32:$K32) -> 8.65 | M32: 3 | N32: 2 | O32: 5 | P32: =SUM('P101'!$M32:$O32) -> 10 | Q32: 3 | R32: 2 | S32: 5 | T32: =SUM('P101'!$Q32:$S32) -> 10 | U32: =('P101'!$L32+'P101'!$P32+'P101'!$T32)*'P101'!$F32 -> 27.617226 | V32: 4.6 | W32: 8.3 | X32: =SUM('P101'!$V32:$W32)*'P101'!$G32 -> 13.575411 | Y32: 1 | Z32: 0 | AA32: 5 | AB32: =IF(SUM('P101'!$Y32:$AA32)>5.9,"SI","NO") -> SI | AC32: =SUM('P101'!$Y32:$AA32) -> 6 | AD32: 2 | AE32: 4 | AF32: =IF('P101'!$AG32>5.9,"SI","NO") -> SI | AG32: =SUM('P101'!$AD32:$AE32) -> 6 | AH32: 4.5 | AI32: 4.5 | AJ32: =AVERAGE('P101'!$AH32:$AI32)*'P101'!$H32 -> 2.25 | AK32: 1 | AL32: 8.5 | AM32: 8.5 | AN32: =(('P101'!$AL32+'P101'!$AM32))*'P101'!$AK32 -> 17 | AO32: 10 | AP32: =SUM('P101'!$U32) -> 27.617226 | AQ32: =SUM(AN32,AJ32,AG32,AC32,X32,'P101'!$AO32) -> 54.825411 | AR32: ='P101'!$AP32+'P101'!$AQ32 -> 82.442637
A33: jopaguay@espol.edu.ec | B33: 202501904 | C33: PAGUAY GOMEZ JOSE DANIEL | D33: 9 | F33: 1.0552657 | G33: 1.0806865 | H33: 1.0073724 | I33: 3 | J33: 1.25 | K33: 4.15 | L33: =SUM('P101'!$I33:$K33) -> 8.4 | M33: 3 | N33: 2 | O33: 5 | P33: =SUM('P101'!$M33:$O33) -> 10 | Q33: 0.75 | R33: 1.5 | S33: 0 | T33: =SUM('P101'!$Q33:$S33) -> 2.25 | U33: =('P101'!$L33+'P101'!$P33+'P101'!$T33)*'P101'!$F33 -> 21.791237 | V33: 4.55 | W33: 3.1 | X33: =SUM('P101'!$V33:$W33)*'P101'!$G33 -> 8.2672514 | Y33: 1 | Z33: 0 | AA33: 1.25 | AB33: =IF(SUM('P101'!$Y33:$AA33)>5.9,"SI","NO") -> NO | AC33: =SUM('P101'!$Y33:$AA33) -> 2.25 | AD33: 1 | AE33: 5 | AF33: =IF('P101'!$AG33>5.9,"SI","NO") -> SI | AG33: =SUM('P101'!$AD33:$AE33) -> 6 | AH33: 0 | AI33: 0 | AJ33: =AVERAGE('P101'!$AH33:$AI33)*'P101'!$H33 -> 0 | AK33: 0 | AL33: 0 | AM33: 0 | AN33: =(('P101'!$AL33+'P101'!$AM33))*'P101'!$AK33 -> 0 | AO33: 5.5 | AP33: =SUM('P101'!$U33) -> 21.791237 | AQ33: =SUM(AN33,AJ33,AG33,AC33,X33,'P101'!$AO33) -> 22.017251 | AR33: ='P101'!$AP33+'P101'!$AQ33 -> 43.808489
A34: adriapaz@espol.edu.ec | B34: 202506929 | C34: PAZ BRITO ADRIAN ALEJANDRO | D34: 10 | F34: 1 | G34: 0.9769268 | H34: 1.0192944 | I34: 3 | J34: 2 | K34: 4.7 | L34: =SUM('P101'!$I34:$K34) -> 9.7 | M34: 3 | N34: 2 | O34: 5 | P34: =SUM('P101'!$M34:$O34) -> 10 | Q34: 1 | R34: 2 | S34: 0 | T34: =SUM('P101'!$Q34:$S34) -> 3 | U34: =('P101'!$L34+'P101'!$P34+'P101'!$T34)*'P101'!$F34 -> 22.7 | V34: 4.05 | W34: 6 | X34: =SUM('P101'!$V34:$W34)*'P101'!$G34 -> 9.8181143 | Y34: 2 | Z34: 1.5 | AA34: 2.5 | AB34: =IF(SUM('P101'!$Y34:$AA34)>5.9,"SI","NO") -> SI | AC34: =SUM('P101'!$Y34:$AA34) -> 6 | AD34: 1.5 | AE34: 5 | AF34: =IF('P101'!$AG34>5.9,"SI","NO") -> SI | AG34: =SUM('P101'!$AD34:$AE34) -> 6.5 | AH34: 0 | AI34: 0 | AJ34: =AVERAGE('P101'!$AH34:$AI34)*'P101'!$H34 -> 0 | AK34: 0 | AL34: 0 | AM34: 0 | AN34: =(('P101'!$AL34+'P101'!$AM34))*'P101'!$AK34 -> 0 | AO34: 8.5 | AP34: =SUM('P101'!$U34) -> 22.7 | AQ34: =SUM(AN34,AJ34,AG34,AC34,X34,'P101'!$AO34) -> 30.818114 | AR34: ='P101'!$AP34+'P101'!$AQ34 -> 53.518114
A35: jerepazm@espol.edu.ec | B35: 202507158 | C35: PAZMIÃ‘O PADILLA JEREMY ARTURO | D35: 8 | F35: 0.86886329 | G35: 0.5 | H35: 0.99477803 | I35: 3 | J35: 1.25 | K35: 2.1 | L35: =SUM('P101'!$I35:$K35) -> 6.35 | M35: 0 | N35: 0 | O35: 0 | P35: =SUM('P101'!$M35:$O35) -> 0 | Q35: 2.25 | R35: 2 | S35: 0 | T35: =SUM('P101'!$Q35:$S35) -> 4.25 | U35: =('P101'!$L35+'P101'!$P35+'P101'!$T35)*'P101'!$F35 -> 9.2099509 | V35: 4.4 | W35: 7.3 | X35: =SUM('P101'!$V35:$W35)*'P101'!$G35 -> 5.85 | Y35: 1 | Z35: 0 | AA35: 2.5 | AB35: =IF(SUM('P101'!$Y35:$AA35)>5.9,"SI","NO") -> NO | AC35: =SUM('P101'!$Y35:$AA35) -> 3.5 | AD35: 2 | AE35: 4 | AF35: =IF('P101'!$AG35>5.9,"SI","NO") -> SI | AG35: =SUM('P101'!$AD35:$AE35) -> 6 | AH35: 4 | AI35: 0 | AJ35: =AVERAGE('P101'!$AH35:$AI35)*'P101'!$H35 -> 1.9895561 | AK35: 1 | AL35: 0 | AM35: 0 | AN35: =(('P101'!$AL35+'P101'!$AM35))*'P101'!$AK35 -> 0 | AO35: 9.5 | AP35: =SUM('P101'!$U35) -> 9.2099509 | AQ35: =SUM(AN35,AJ35,AG35,AC35,X35,'P101'!$AO35) -> 26.839556 | AR35: ='P101'!$AP35+'P101'!$AQ35 -> 36.049507
A36: livperal@espol.edu.ec | B36: 202502837 | C36: PERALTA SANCHEZ LIVINTON STEVEN | D36: 1 | F36: 1.1170441 | G36: 1.069045 | H36: 1.3207426 | I36: 3 | J36: 1.25 | K36: 5 | L36: =SUM('P101'!$I36:$K36) -> 9.25 | M36: 3 | N36: 2 | O36: 5 | P36: =SUM('P101'!$M36:$O36) -> 10 | Q36: 1.25 | R36: 1.75 | S36: 2.8 | T36: =SUM('P101'!$Q36:$S36) -> 5.8 | U36: =('P101'!$L36+'P101'!$P36+'P101'!$T36)*'P101'!$F36 -> 27.981956 | V36: 4.65 | W36: 6.8 | X36: =SUM('P101'!$V36:$W36)*'P101'!$G36 -> 12.240565 | Y36: 1.5 | Z36: 0 | AA36: 5 | AB36: =IF(SUM('P101'!$Y36:$AA36)>5.9,"SI","NO") -> SI | AC36: =SUM('P101'!$Y36:$AA36) -> 6.5 | AD36: 1.5 | AE36: 5.5 | AF36: =IF('P101'!$AG36>5.9,"SI","NO") -> SI | AG36: =SUM('P101'!$AD36:$AE36) -> 7 | AH36: 4 | AI36: 5 | AJ36: =AVERAGE('P101'!$AH36:$AI36)*'P101'!$H36 -> 5.9433415 | AK36: 1 | AL36: 6 | AM36: 8 | AN36: =(('P101'!$AL36+'P101'!$AM36))*'P101'!$AK36 -> 14 | AO36: 9.75 | AP36: =SUM('P101'!$U36) -> 27.981956 | AQ36: =SUM(AN36,AJ36,AG36,AC36,X36,'P101'!$AO36) -> 55.433906 | AR36: ='P101'!$AP36+'P101'!$AQ36 -> 83.415862
A37: marplata@espol.edu.ec | B37: 202202586 | C37: PEREZ LATA MARIO ROGELIO | D37: 8 | F37: 1.0248552 | G37: 0.99849737 | H37: 0.99477803 | I37: 2.25 | J37: 1.25 | K37: 2.1 | L37: =SUM('P101'!$I37:$K37) -> 5.6 | M37: 3 | N37: 2 | O37: 5 | P37: =SUM('P101'!$M37:$O37) -> 10 | Q37: 2.25 | R37: 2 | S37: 3.85 | T37: =SUM('P101'!$Q37:$S37) -> 8.1 | U37: =('P101'!$L37+'P101'!$P37+'P101'!$T37)*'P101'!$F37 -> 24.289069 | V37: 4.4 | W37: 7.3 | X37: =SUM('P101'!$V37:$W37)*'P101'!$G37 -> 11.682419 | Y37: 2 | Z37: 0 | AA37: 4 | AB37: =IF(SUM('P101'!$Y37:$AA37)>5.9,"SI","NO") -> SI | AC37: =SUM('P101'!$Y37:$AA37) -> 6 | AD37: 2 | AE37: 4 | AF37: =IF('P101'!$AG37>5.9,"SI","NO") -> SI | AG37: =SUM('P101'!$AD37:$AE37) -> 6 | AH37: 4 | AI37: 5 | AJ37: =AVERAGE('P101'!$AH37:$AI37)*'P101'!$H37 -> 4.4765011 | AK37: 1 | AL37: 7 | AM37: 7 | AN37: =(('P101'!$AL37+'P101'!$AM37))*'P101'!$AK37 -> 14 | AO37: 9.5 | AP37: =SUM('P101'!$U37) -> 24.289069 | AQ37: =SUM(AN37,AJ37,AG37,AC37,X37,'P101'!$AO37) -> 51.65892 | AR37: ='P101'!$AP37+'P101'!$AQ37 -> 75.947989
A38: ariperez@espol.edu.ec | B38: 202501276 | C38: PEREZ LINO ARIEL ALEJANDRO | D38: 10 | F38: 1 | G38: 1.0052494 | H38: 1.0192944 | I38: 2.25 | J38: 2 | K38: 4.7 | L38: =SUM('P101'!$I38:$K38) -> 8.95 | M38: 3 | N38: 2 | O38: 5 | P38: =SUM('P101'!$M38:$O38) -> 10 | Q38: 2.25 | R38: 2 | S38: 4.45 | T38: =SUM('P101'!$Q38:$S38) -> 8.7 | U38: =('P101'!$L38+'P101'!$P38+'P101'!$T38)*'P101'!$F38 -> 27.65 | V38: 4.05 | W38: 6 | X38: =SUM('P101'!$V38:$W38)*'P101'!$G38 -> 10.102756 | Y38: 2 | Z38: 1.5 | AA38: 3.75 | AB38: =IF(SUM('P101'!$Y38:$AA38)>5.9,"SI","NO") -> SI | AC38: =SUM('P101'!$Y38:$AA38) -> 7.25 | AD38: 1.5 | AE38: 5 | AF38: =IF('P101'!$AG38>5.9,"SI","NO") -> SI | AG38: =SUM('P101'!$AD38:$AE38) -> 6.5 | AH38: 0 | AI38: 0 | AJ38: =AVERAGE('P101'!$AH38:$AI38)*'P101'!$H38 -> 0 | AK38: 0 | AL38: 0 | AM38: 0 | AN38: =(('P101'!$AL38+'P101'!$AM38))*'P101'!$AK38 -> 0 | AO38: 8.5 | AP38: =SUM('P101'!$U38) -> 27.65 | AQ38: =SUM(AN38,AJ38,AG38,AC38,X38,'P101'!$AO38) -> 32.352756 | AR38: ='P101'!$AP38+'P101'!$AQ38 -> 60.002756
A39: ceproano@espol.edu.ec | B39: 202504981 | C39: PROAÃ‘O GUERRERO CESAR DAVID | D39: 4 | F39: 1.0517579 | G39: 1.0831646 | H39: 1.0088891 | I39: 3 | J39: 0.75 | K39: 4.9 | L39: =SUM('P101'!$I39:$K39) -> 8.65 | M39: 3 | N39: 2 | O39: 5 | P39: =SUM('P101'!$M39:$O39) -> 10 | Q39: 0.88 | R39: 2 | S39: 0 | T39: =SUM('P101'!$Q39:$S39) -> 2.88 | U39: =('P101'!$L39+'P101'!$P39+'P101'!$T39)*'P101'!$F39 -> 22.644348 | V39: 4.6 | W39: 8.3 | X39: =SUM('P101'!$V39:$W39)*'P101'!$G39 -> 13.972824 | Y39: 1.5 | Z39: 0 | AA39: 3 | AB39: =IF(SUM('P101'!$Y39:$AA39)>5.9,"SI","NO") -> NO | AC39: =SUM('P101'!$Y39:$AA39) -> 4.5 | AD39: 2 | AE39: 4 | AF39: =IF('P101'!$AG39>5.9,"SI","NO") -> SI | AG39: =SUM('P101'!$AD39:$AE39) -> 6 | AH39: 4.5 | AI39: 4.5 | AJ39: =AVERAGE('P101'!$AH39:$AI39)*'P101'!$H39 -> 4.5400008 | AK39: 1 | AL39: 0 | AM39: 0 | AN39: =(('P101'!$AL39+'P101'!$AM39))*'P101'!$AK39 -> 0 | AO39: 10 | AP39: =SUM('P101'!$U39) -> 22.644348 | AQ39: =SUM(AN39,AJ39,AG39,AC39,X39,'P101'!$AO39) -> 39.012825 | AR39: ='P101'!$AP39+'P101'!$AQ39 -> 61.657172
A40: rafaquin@espol.edu.ec | B40: 202509444 | C40: QUIÃ‘ONEZ ABARCA RAFAELA ALEJANDRA | D40: 10 | F40: 1 | G40: 1.0052494 | H40: 1.0192944 | I40: 3 | J40: 2 | K40: 4.7 | L40: =SUM('P101'!$I40:$K40) -> 9.7 | M40: 3 | N40: 2 | O40: 5 | P40: =SUM('P101'!$M40:$O40) -> 10 | Q40: 2.25 | R40: 2 | S40: 4.45 | T40: =SUM('P101'!$Q40:$S40) -> 8.7 | U40: =('P101'!$L40+'P101'!$P40+'P101'!$T40)*'P101'!$F40 -> 28.4 | V40: 4.05 | W40: 6 | X40: =SUM('P101'!$V40:$W40)*'P101'!$G40 -> 10.102756 | Y40: 1.5 | Z40: 2.3 | AA40: 3.75 | AB40: =IF(SUM('P101'!$Y40:$AA40)>5.9,"SI","NO") -> SI | AC40: =SUM('P101'!$Y40:$AA40) -> 7.55 | AD40: 1.5 | AE40: 5 | AF40: =IF('P101'!$AG40>5.9,"SI","NO") -> SI | AG40: =SUM('P101'!$AD40:$AE40) -> 6.5 | AH40: 0 | AI40: 0 | AJ40: =AVERAGE('P101'!$AH40:$AI40)*'P101'!$H40 -> 0 | AK40: 0 | AL40: 0 | AM40: 0 | AN40: =(('P101'!$AL40+'P101'!$AM40))*'P101'!$AK40 -> 0 | AO40: 8.5 | AP40: =SUM('P101'!$U40) -> 28.4 | AQ40: =SUM(AN40,AJ40,AG40,AC40,X40,'P101'!$AO40) -> 32.652756 | AR40: ='P101'!$AP40+'P101'!$AQ40 -> 61.052756
A41: ferramos@espol.edu.ec | B41: 202509394 | C41: RAMOS YAGUAL FERNANDO JOSE | D41: 9 | F41: 0.97290692 | G41: 0.973 | H41: 0.96740391 | I41: 2.25 | J41: 1.25 | K41: 4.15 | L41: =SUM('P101'!$I41:$K41) -> 7.65 | M41: 3 | N41: 2 | O41: 5 | P41: =SUM('P101'!$M41:$O41) -> 10 | Q41: 0 | R41: 1.5 | S41: 0 | T41: =SUM('P101'!$Q41:$S41) -> 1.5 | U41: =('P101'!$L41+'P101'!$P41+'P101'!$T41)*'P101'!$F41 -> 18.631168 | V41: 4.55 | W41: 3.1 | X41: =SUM('P101'!$V41:$W41)*'P101'!$G41 -> 7.44345 | Y41: 1 | Z41: 0 | AA41: 5 | AB41: =IF(SUM('P101'!$Y41:$AA41)>5.9,"SI","NO") -> SI | AC41: =SUM('P101'!$Y41:$AA41) -> 6 | AD41: 1 | AE41: 5 | AF41: =IF('P101'!$AG41>5.9,"SI","NO") -> SI | AG41: =SUM('P101'!$AD41:$AE41) -> 6 | AH41: 0 | AI41: 0 | AJ41: =AVERAGE('P101'!$AH41:$AI41)*'P101'!$H41 -> 0 | AK41: 0 | AL41: 0 | AM41: 0 | AN41: =(('P101'!$AL41+'P101'!$AM41))*'P101'!$AK41 -> 0 | AO41: 5.5 | AP41: =SUM('P101'!$U41) -> 18.631168 | AQ41: =SUM(AN41,AJ41,AG41,AC41,X41,'P101'!$AO41) -> 24.94345 | AR41: ='P101'!$AP41+'P101'!$AQ41 -> 43.574618
A42: andreyes@espol.edu.ec | B42: 202509667 | C42: REYES GALARZA ANDRE DAVID | D42: 10 | F42: 1 | G42: 0.5 | H42: 0.91168461 | I42: 2.25 | J42: 2 | K42: 4.7 | L42: =SUM('P101'!$I42:$K42) -> 8.95 | M42: 3 | N42: 2 | O42: 5 | P42: =SUM('P101'!$M42:$O42) -> 10 | Q42: 0 | R42: 2 | S42: 0 | T42: =SUM('P101'!$Q42:$S42) -> 2 | U42: =('P101'!$L42+'P101'!$P42+'P101'!$T42)*'P101'!$F42 -> 20.95 | V42: 4.05 | W42: 6 | X42: =SUM('P101'!$V42:$W42)*'P101'!$G42 -> 5.025 | Y42: 1.5 | Z42: 3 | AA42: 3.75 | AB42: =IF(SUM('P101'!$Y42:$AA42)>5.9,"SI","NO") -> SI | AC42: =SUM('P101'!$Y42:$AA42) -> 8.25 | AD42: 1.5 | AE42: 5 | AF42: =IF('P101'!$AG42>5.9,"SI","NO") -> SI | AG42: =SUM('P101'!$AD42:$AE42) -> 6.5 | AH42: 0 | AI42: 0 | AJ42: =AVERAGE('P101'!$AH42:$AI42)*'P101'!$H42 -> 0 | AK42: 0 | AL42: 0 | AM42: 0 | AN42: =(('P101'!$AL42+'P101'!$AM42))*'P101'!$AK42 -> 0 | AO42: 8.5 | AP42: =SUM('P101'!$U42) -> 20.95 | AQ42: =SUM(AN42,AJ42,AG42,AC42,X42,'P101'!$AO42) -> 28.275 | AR42: ='P101'!$AP42+'P101'!$AQ42 -> 49.225
...

Sheet P102
D1: P102 | F1: Coevaluaciones | I1: Actividades Práctico-Experimental (APE) (30%) | V1: AVANCES (15%) | Y1: VALIDACION INDIVIDUAL (10%) | AD1: VALIDACION DE PROTOTIPO (10%) | AH1: PROTOTIPO (5%) | AK1: EXPOSICION Y DEFENSA (20%) | AO1: REPORTE (10%) | AP1: TOTAL (100%)
A2: Correo | B2: Número de Matrícula | C2: Apellidos y Nombres | D2: Grupo | E2: Vez | F2: WF1 (APE) | G2: WF2 (AVANCE) | H2: WF3 (FINALES) | I2: CL1 | J2: HT1 | K2: RPAPE1 | L2: APE1 | M2: CL2 | N2: HT2 | O2: RPAPE2 | P2: APE2 | Q2: CL3 | R2: HT3 | S2: RPAPE3 | T2: APE3 | U2: APE_total | V2: AV1 | W2: AV2 | X2: AV_total | Y2: VI1 | Z2: VI2 | AA2: VI3 | AB2: VI_STATUS | AC2: VI_TOTAL | AD2: VP1 | AE2: VP2 | AF2: VP_STATUS | AG2: VP_TOTAL | AH2: EV1_P | AI2: EV2_P | AJ2: PROT_TOTAL | AK2: POSTER | AL2: JUR_1 | AM2: JUR_2 | AN2: EXP_TOTAL | AO2: REPORTE | AP2: EXP | AQ2: PROY | AR2: AL ACADEMICO
A3: prueba | B3: prueba | C3: ESTUDIANTE DE PRUEBA | D3: 0 | E3: 1 | F3: 1 | G3: 1 | H3: 1 | I3: 3 | J3: 2 | K3: 5 | L3: =SUM('P102'!$I3:$K3) -> 10 | M3: 3 | N3: 2 | O3: 5 | P3: =SUM('P102'!$M3:$O3) -> 10 | Q3: 3 | R3: 2 | S3: 5 | T3: =SUM('P102'!$Q3:$S3) -> 10 | U3: =('P102'!$L3+'P102'!$P3+'P102'!$T3)*'P102'!$F3 -> 30 | V3: 5 | W3: 10 | X3: =SUM('P102'!$V3:$W3)*'P102'!$G3 -> 15 | Y3: 2 | Z3: 3 | AA3: 5 | AB3: =IF(SUM('P102'!$Y3:$AA3)>5.9,"SI","NO") -> SI | AC3: =SUM('P102'!$Y3:$AA3) -> 10 | AD3: 2 | AE3: 8 | AF3: =IF('P102'!$AG3>5.9,"SI","NO") -> SI | AG3: =SUM('P102'!$AD3:$AE3) -> 10 | AH3: 5 | AI3: 5 | AJ3: =AVERAGE('P102'!$AH3:$AI3)*'P102'!$H3 -> 5 | AK3: 1 | AL3: 10 | AM3: 10 | AN3: =(1*('P102'!$AL3+'P102'!$AM3))*'P102'!$AK3 -> 20 | AO3: 10 | AP3: =SUM('P102'!$U3) -> 30 | AQ3: =SUM(AN3,AJ3,AG3,AC3,X3,('P102'!$AO3)*H3) -> 70 | AR3: ='P102'!$AP3+'P102'!$AQ3 -> 100
A4: eriandra@espol.edu.ec | B4: 202411948 | C4: ANDRADE HOLGUIN ERICK ARIEL | D4: 7 | F4: 0.5 | G4: 1.0293102 | H4: 0.5 | I4: 2.25 | J4: 2 | K4: 4.3 | L4: =IF(I4<1.79,SUM(I4:J4), SUM('P102'!$Q4:$S4)) -> 7.7 | M4: 2.25 | N4: 1.75 | O4: 3.7 | P4: =IF(M4<1.79,SUM(M4:N4), SUM('P102'!$Q4:$S4)) -> 7.7 | Q4: 2.25 | R4: 1.75 | S4: 3.7 | T4: =IF(Q4<1.79,SUM(Q4:R4), SUM('P102'!$Q4:$S4)) -> 7.7 | U4: =('P102'!$L4+'P102'!$P4+'P102'!$T4)*'P102'!$F4 -> 11.55 | V4: 3.55 | W4: 7 | X4: =SUM('P102'!$V4:$W4)*'P102'!$G4 -> 10.859223 | Y4: 1.5 | Z4: 0 | AA4: 2.5 | AB4: =IF(SUM('P102'!$Y4:$AA4)>5.9,"SI","NO") -> NO | AC4: =SUM('P102'!$Y4:$AA4) -> 4 | AD4: 0 | AE4: 4 | AF4: =IF('P102'!$AG4>5.9,"SI","NO") -> NO | AG4: =SUM('P102'!$AD4:$AE4) -> 4 | AH4: =IF('P102'!$AF4="NO",0," ") -> 0 | AI4: =IF('P102'!$AF4="NO",0," ") -> 0 | AJ4: =AVERAGE('P102'!$AH4:$AI4)*'P102'!$H4 -> 0 | AK4: 0 | AL4: 0 | AM4: 0 | AN4: =(1*('P102'!$AL4+'P102'!$AM4))*'P102'!$AK4 -> 0 | AO4: 7.25 | AP4: =SUM('P102'!$U4) -> 11.55 | AQ4: =SUM(AN4,AJ4,AG4,AC4,X4,('P102'!$AO4)*H4) -> 22.484223 | AR4: ='P102'!$AP4+'P102'!$AQ4 -> 34.034223
A5: joseavil@espol.edu.ec | B5: 202411559 | C5: AVILA ZAMBRANO JOSE ANDRES | D5: 6 | F5: 1.2171612 | G5: 1.2403473 | H5: 0.5 | I5: 2.25 | J5: 2 | K5: 4.2 | L5: =IF(I5<1.79,SUM(I5:J5), SUM('P102'!$Q5:$S5)) -> 4.25 | M5: 2.25 | N5: 2 | O5: 0 | P5: =IF(M5<1.79,SUM(M5:N5), SUM('P102'!$Q5:$S5)) -> 4.25 | Q5: 2.25 | R5: 2 | S5: 0 | T5: =IF(Q5<1.79,SUM(Q5:R5), SUM('P102'!$Q5:$S5)) -> 4.25 | U5: =('P102'!$L5+'P102'!$P5+'P102'!$T5)*'P102'!$F5 -> 15.518806 | V5: 4.3 | W5: 8 | X5: =SUM('P102'!$V5:$W5)*'P102'!$G5 -> 15.256272 | Y5: 1 | Z5: 3 | AA5: 5 | AB5: =IF(SUM('P102'!$Y5:$AA5)>5.9,"SI","NO") -> SI | AC5: =SUM('P102'!$Y5:$AA5) -> 9 | AD5: 1 | AE5: 2 | AF5: =IF('P102'!$AG5>5.9,"SI","NO") -> NO | AG5: =SUM('P102'!$AD5:$AE5) -> 3 | AH5: =IF('P102'!$AF5="NO",0," ") -> 0 | AI5: =IF('P102'!$AF5="NO",0," ") -> 0 | AJ5: =AVERAGE('P102'!$AH5:$AI5)*'P102'!$H5 -> 0 | AK5: 0 | AL5: 0 | AM5: 0 | AN5: =(1*('P102'!$AL5+'P102'!$AM5))*'P102'!$AK5 -> 0 | AO5: 7.25 | AP5: =SUM('P102'!$U5) -> 15.518806 | AQ5: =SUM(AN5,AJ5,AG5,AC5,X5,('P102'!$AO5)*H5) -> 30.881272 | AR5: ='P102'!$AP5+'P102'!$AQ5 -> 46.400078
A6: azburneo@espol.edu.ec | B6: 202401386 | C6: BURNEO FARAH AZAEL XAVIER | D6: 2 | F6: 0.5 | G6: 0.5 | H6: 0.5 | I6: 1.5 | J6: 1 | K6: 3 | L6: =IF(I6<1.79,SUM(I6:J6), SUM('P102'!$Q6:$S6)) -> 2.5 | M6: 1.5 | N6: 0 | O6: 0 | P6: =IF(M6<1.79,SUM(M6:N6), SUM('P102'!$Q6:$S6)) -> 1.5 | Q6: 1.5 | R6: 0 | S6: 0 | T6: =IF(Q6<1.79,SUM(Q6:R6), SUM('P102'!$Q6:$S6)) -> 1.5 | U6: =('P102'!$L6+'P102'!$P6+'P102'!$T6)*'P102'!$F6 -> 2.75 | V6: 3.65 | W6: 3.5 | X6: =SUM('P102'!$V6:$W6)*'P102'!$G6 -> 3.575 | Y6: 0.5 | Z6: 0 | AA6: 0 | AB6: =IF(SUM('P102'!$Y6:$AA6)>5.9,"SI","NO") -> NO | AC6: =SUM('P102'!$Y6:$AA6) -> 0.5 | AD6: 1 | AE6: 1 | AF6: =IF('P102'!$AG6>5.9,"SI","NO") -> NO | AG6: =SUM('P102'!$AD6:$AE6) -> 2 | AH6: =IF('P102'!$AF6="NO",0," ") -> 0 | AI6: =IF('P102'!$AF6="NO",0," ") -> 0 | AJ6: =AVERAGE('P102'!$AH6:$AI6)*'P102'!$H6 -> 0 | AK6: 0 | AL6: 0 | AM6: 0 | AN6: =(1*('P102'!$AL6+'P102'!$AM6))*'P102'!$AK6 -> 0 | AO6: 0 | AP6: =SUM('P102'!$U6) -> 2.75 | AQ6: =SUM(AN6,AJ6,AG6,AC6,X6,('P102'!$AO6)*H6) -> 6.075 | AR6: ='P102'!$AP6+'P102'!$AQ6 -> 8.825
A7: isacabal@espol.edu.ec | B7: 202404984 | C7: CABAL RUBIO ISAAC SEBASTIAN | D7: 4 | F7: 1.2146645 | G7: 1.3483997 | H7: 0.5 | I7: 2.25 | J7: 1 | K7: 4.5 | L7: =IF(I7<1.79,SUM(I7:J7), SUM('P102'!$Q7:$S7)) -> 7.45 | M7: 2.25 | N7: 1.5 | O7: 3.7 | P7: =IF(M7<1.79,SUM(M7:N7), SUM('P102'!$Q7:$S7)) -> 7.45 | Q7: 2.25 | R7: 1.5 | S7: 3.7 | T7: =IF(Q7<1.79,SUM(Q7:R7), SUM('P102'!$Q7:$S7)) -> 7.45 | U7: =('P102'!$L7+'P102'!$P7+'P102'!$T7)*'P102'!$F7 -> 27.147751 | V7: 2.6 | W7: 6.4 | X7: =SUM('P102'!$V7:$W7)*'P102'!$G7 -> 12.135598 | Y7: 1 | Z7: 1.5 | AA7: 0 | AB7: =IF(SUM('P102'!$Y7:$AA7)>5.9,"SI","NO") -> NO | AC7: =SUM('P102'!$Y7:$AA7) -> 2.5 | AD7: 1 | AE7: 4 | AF7: =IF('P102'!$AG7>5.9,"SI","NO") -> NO | AG7: =SUM('P102'!$AD7:$AE7) -> 5 | AH7: =IF('P102'!$AF7="NO",0," ") -> 0 | AI7: =IF('P102'!$AF7="NO",0," ") -> 0 | AJ7: =AVERAGE('P102'!$AH7:$AI7)*'P102'!$H7 -> 0 | AK7: 0 | AL7: 0 | AM7: 0 | AN7: =(1*('P102'!$AL7+'P102'!$AM7))*'P102'!$AK7 -> 0 | AO7: 7 | AP7: =SUM('P102'!$U7) -> 27.147751 | AQ7: =SUM(AN7,AJ7,AG7,AC7,X7,('P102'!$AO7)*H7) -> 23.135598 | AR7: ='P102'!$AP7+'P102'!$AQ7 -> 50.283349
A8: juancere@espol.edu.ec | B8: 202406484 | C8: CEREZO CERVANTES JUAN SEBASTIAN | D8: 8 | F8: 0.5 | G8: 0.5 | H8: 0.5 | I8: 2.25 | J8: 2 | K8: 3.8 | L8: =IF(I8<1.79,SUM(I8:J8), SUM('P102'!$Q8:$S8)) -> 2.25 | M8: 2.25 | N8: 0 | O8: 0 | P8: =IF(M8<1.79,SUM(M8:N8), SUM('P102'!$Q8:$S8)) -> 2.25 | Q8: 2.25 | R8: 0 | S8: 0 | T8: =IF(Q8<1.79,SUM(Q8:R8), SUM('P102'!$Q8:$S8)) -> 2.25 | U8: =('P102'!$L8+'P102'!$P8+'P102'!$T8)*'P102'!$F8 -> 3.375 | V8: 3.8 | W8: 8 | X8: =SUM('P102'!$V8:$W8)*'P102'!$G8 -> 5.9 | Y8: 1.5 | Z8: 0 | AA8: 0 | AB8: =IF(SUM('P102'!$Y8:$AA8)>5.9,"SI","NO") -> NO | AC8: =SUM('P102'!$Y8:$AA8) -> 1.5 | AD8: 1 | AE8: 0 | AF8: =IF('P102'!$AG8>5.9,"SI","NO") -> NO | AG8: =SUM('P102'!$AD8:$AE8) -> 1 | AH8: =IF('P102'!$AF8="NO",0," ") -> 0 | AI8: =IF('P102'!$AF8="NO",0," ") -> 0 | AJ8: =AVERAGE('P102'!$AH8:$AI8)*'P102'!$H8 -> 0 | AK8: 0 | AL8: 0 | AM8: 0 | AN8: =(1*('P102'!$AL8+'P102'!$AM8))*'P102'!$AK8 -> 0 | AO8: 0 | AP8: =SUM('P102'!$U8) -> 3.375 | AQ8: =SUM(AN8,AJ8,AG8,AC8,X8,('P102'!$AO8)*H8) -> 8.4 | AR8: ='P102'!$AP8+'P102'!$AQ8 -> 11.775
A9: logacisn@espol.edu.ec | B9: 202401287 | C9: CISNEROS ESPIN LOGAN MISAEL | D9: 8 | F9: 1.25 | G9: 1.25 | H9: 1.25 | I9: 3 | J9: 2 | K9: 3.8 | L9: =IF(I9<1.79,SUM(I9:J9), SUM('P102'!$Q9:$S9)) -> 4.5 | M9: 3 | N9: 0 | O9: 0 | P9: =IF(M9<1.79,SUM(M9:N9), SUM('P102'!$Q9:$S9)) -> 4.5 | Q9: 3 | R9: 1.5 | S9: 0 | T9: =IF(Q9<1.79,SUM(Q9:R9), SUM('P102'!$Q9:$S9)) -> 4.5 | U9: =('P102'!$L9+'P102'!$P9+'P102'!$T9)*'P102'!$F9 -> 16.875 | V9: 3.8 | W9: 8 | X9: =SUM('P102'!$V9:$W9)*'P102'!$G9 -> 14.75 | Y9: 1.5 | Z9: 1.5 | AA9: 1.25 | AB9: =IF(SUM('P102'!$Y9:$AA9)>5.9,"SI","NO") -> NO | AC9: =SUM('P102'!$Y9:$AA9) -> 4.25 | AD9: 1 | AE9: 4.5 | AF9: =IF('P102'!$AG9>5.9,"SI","NO") -> NO | AG9: =SUM('P102'!$AD9:$AE9) -> 5.5 | AH9: =IF('P102'!$AF9="NO",0," ") -> 0 | AI9: =IF('P102'!$AF9="NO",0," ") -> 0 | AJ9: =AVERAGE('P102'!$AH9:$AI9)*'P102'!$H9 -> 0 | AK9: 0 | AL9: 0 | AM9: 0 | AN9: =(1*('P102'!$AL9+'P102'!$AM9))*'P102'!$AK9 -> 0 | AO9: 8 | AP9: =SUM('P102'!$U9) -> 16.875 | AQ9: =SUM(AN9,AJ9,AG9,AC9,X9,('P102'!$AO9)*H9) -> 34.5 | AR9: ='P102'!$AP9+'P102'!$AQ9 -> 51.375
A10: maconsue@espol.edu.ec | B10: 202210589 | C10: CONSUEGRA ABAD MARIO ALEXANDER | D10: 4 | F10: 1.1161996 | G10: 1.1547005 | H10: 0.5 | I10: 3 | J10: 1 | K10: 4.5 | L10: =IF(I10<1.79,SUM(I10:J10), SUM('P102'!$Q10:$S10)) -> 8.2 | M10: 3 | N10: 1.5 | O10: 3.7 | P10: =IF(M10<1.79,SUM(M10:N10), SUM('P102'!$Q10:$S10)) -> 8.2 | Q10: 3 | R10: 1.5 | S10: 3.7 | T10: =IF(Q10<1.79,SUM(Q10:R10), SUM('P102'!$Q10:$S10)) -> 8.2 | U10: =('P102'!$L10+'P102'!$P10+'P102'!$T10)*'P102'!$F10 -> 27.458511 | V10: 2.6 | W10: 6.41 | X10: =SUM('P102'!$V10:$W10)*'P102'!$G10 -> 10.403852 | Y10: 1.5 | Z10: 0 | AA10: 0 | AB10: =IF(SUM('P102'!$Y10:$AA10)>5.9,"SI","NO") -> NO | AC10: =SUM('P102'!$Y10:$AA10) -> 1.5 | AD10: 1 | AE10: 4 | AF10: =IF('P102'!$AG10>5.9,"SI","NO") -> NO | AG10: =SUM('P102'!$AD10:$AE10) -> 5 | AH10: =IF('P102'!$AF10="NO",0," ") -> 0 | AI10: =IF('P102'!$AF10="NO",0," ") -> 0 | AJ10: =AVERAGE('P102'!$AH10:$AI10)*'P102'!$H10 -> 0 | AK10: 0 | AL10: 0 | AM10: 0 | AN10: =(1*('P102'!$AL10+'P102'!$AM10))*'P102'!$AK10 -> 0 | AO10: 7 | AP10: =SUM('P102'!$U10) -> 27.458511 | AQ10: =SUM(AN10,AJ10,AG10,AC10,X10,('P102'!$AO10)*H10) -> 20.403852 | AR10: ='P102'!$AP10+'P102'!$AQ10 -> 47.862363
A11: ancuesta@espol.edu.ec | B11: 202502266 | C11: CUESTA YAGUAL ANDERSON VICTOR | D11: 3 | F11: 1.1547005 | G11: 1.1547005 | H11: 1.1547005 | I11: 2.25 | J11: 1.25 | K11: 4.75 | L11: =IF(I11<1.79,SUM(I11:J11), SUM('P102'!$Q11:$S11)) -> 7.85 | M11: 2.25 | N11: 2 | O11: 3.6 | P11: =IF(M11<1.79,SUM(M11:N11), SUM('P102'!$Q11:$S11)) -> 7.85 | Q11: 2.25 | R11: 2 | S11: 3.6 | T11: =IF(Q11<1.79,SUM(Q11:R11), SUM('P102'!$Q11:$S11)) -> 7.85 | U11: =('P102'!$L11+'P102'!$P11+'P102'!$T11)*'P102'!$F11 -> 27.193198 | V11: 4.15 | W11: 8.1 | X11: =SUM('P102'!$V11:$W11)*'P102'!$G11 -> 14.145082 | Y11: 1.5 | Z11: 1.5 | AA11: 1.25 | AB11: =IF(SUM('P102'!$Y11:$AA11)>5.9,"SI","NO") -> NO | AC11: =SUM('P102'!$Y11:$AA11) -> 4.25 | AD11: 1 | AE11: 6 | AF11: =IF('P102'!$AG11>5.9,"SI","NO") -> SI | AG11: =SUM('P102'!$AD11:$AE11) -> 7 | AH11: 4 | AI11: 3.5 | AJ11: =AVERAGE('P102'!$AH11:$AI11)*'P102'!$H11 -> 4.330127 | AK11: 0 | AL11: 0 | AM11: 0 | AN11: =(1*('P102'!$AL11+'P102'!$AM11))*'P102'!$AK11 -> 0 | AO11: 9.25 | AP11: =SUM('P102'!$U11) -> 27.193198 | AQ11: =SUM(AN11,AJ11,AG11,AC11,X11,('P102'!$AO11)*H11) -> 40.406189 | AR11: ='P102'!$AP11+'P102'!$AQ11 -> 67.599386
A12: juanenca@espol.edu.ec | B12: 202407235 | C12: ENCARNACION GILER JUAN JOSE | D12: 6 | F12: 1.1243654 | G12: 1.2264883 | H12: 1.1547005 | I12: 2.25 | J12: 2 | K12: 4.2 | L12: =IF(I12<1.79,SUM(I12:J12), SUM('P102'!$Q12:$S12)) -> 8.25 | M12: 2.25 | N12: 2 | O12: 4 | P12: =IF(M12<1.79,SUM(M12:N12), SUM('P102'!$Q12:$S12)) -> 8.25 | Q12: 2.25 | R12: 2 | S12: 4 | T12: =IF(Q12<1.79,SUM(Q12:R12), SUM('P102'!$Q12:$S12)) -> 8.25 | U12: =('P102'!$L12+'P102'!$P12+'P102'!$T12)*'P102'!$F12 -> 27.828043 | V12: 4.3 | W12: 8 | X12: =SUM('P102'!$V12:$W12)*'P102'!$G12 -> 15.085806 | Y12: 1.5 | Z12: 0 | AA12: 1.25 | AB12: =IF(SUM('P102'!$Y12:$AA12)>5.9,"SI","NO") -> NO | AC12: =SUM('P102'!$Y12:$AA12) -> 2.75 | AD12: 1 | AE12: 2 | AF12: =IF('P102'!$AG12>5.9,"SI","NO") -> NO | AG12: =SUM('P102'!$AD12:$AE12) -> 3 | AH12: =IF('P102'!$AF12="NO",0," ") -> 0 | AI12: =IF('P102'!$AF12="NO",0," ") -> 0 | AJ12: =AVERAGE('P102'!$AH12:$AI12)*'P102'!$H12 -> 0 | AK12: 0 | AL12: 0 | AM12: 0 | AN12: =(1*('P102'!$AL12+'P102'!$AM12))*'P102'!$AK12 -> 0 | AO12: 7.25 | AP12: =SUM('P102'!$U12) -> 27.828043 | AQ12: =SUM(AN12,AJ12,AG12,AC12,X12,('P102'!$AO12)*H12) -> 29.207385 | AR12: ='P102'!$AP12+'P102'!$AQ12 -> 57.035428
A13: diespino@espol.edu.ec | B13: 202416608 | C13: ESPINOZA JIMENEZ DIEGO ANDRES | D13: 8 | F13: 0.5 | G13: 0 | H13: 0 | I13: 3 | J13: 2 | K13: 0 | L13: =IF(I13<1.79,SUM(I13:J13), SUM('P102'!$Q13:$S13)) -> 3 | M13: 3 | N13: 0 | O13: 0 | P13: =IF(M13<1.79,SUM(M13:N13), SUM('P102'!$Q13:$S13)) -> 3 | Q13: 3 | R13: 0 | S13: 0 | T13: =IF(Q13<1.79,SUM(Q13:R13), SUM('P102'!$Q13:$S13)) -> 3 | U13: =('P102'!$L13+'P102'!$P13+'P102'!$T13)*'P102'!$F13 -> 4.5 | V13: 3.8 | W13: 8 | X13: =SUM('P102'!$V13:$W13)*'P102'!$G13 -> 0 | Y13: 0.5 | Z13: 0 | AA13: 0 | AB13: =IF(SUM('P102'!$Y13:$AA13)>5.9,"SI","NO") -> NO | AC13: =SUM('P102'!$Y13:$AA13) -> 0.5 | AD13: 1 | AE13: 0 | AF13: =IF('P102'!$AG13>5.9,"SI","NO") -> NO | AG13: =SUM('P102'!$AD13:$AE13) -> 1 | AH13: =IF('P102'!$AF13="NO",0," ") -> 0 | AI13: =IF('P102'!$AF13="NO",0," ") -> 0 | AJ13: =AVERAGE('P102'!$AH13:$AI13)*'P102'!$H13 -> 0 | AK13: 0 | AL13: 0 | AM13: 0 | AN13: =(1*('P102'!$AL13+'P102'!$AM13))*'P102'!$AK13 -> 0 | AO13: 0 | AP13: =SUM('P102'!$U13) -> 4.5 | AQ13: =SUM(AN13,AJ13,AG13,AC13,X13,('P102'!$AO13)*H13) -> 1.5 | AR13: ='P102'!$AP13+'P102'!$AQ13 -> 6
A14: jdfarino@espol.edu.ec | B14: 202207783 | C14: FARIÑO SANCHEZ JEAN DAVID | D14: 4 | F14: 0.5 | G14: 0.5 | H14: 0.5 | I14: 2.25 | J14: 1 | K14: 4.5 | L14: =IF(I14<1.79,SUM(I14:J14), SUM('P102'!$Q14:$S14)) -> 3.75 | M14: 2.25 | N14: 1.5 | O14: 0 | P14: =IF(M14<1.79,SUM(M14:N14), SUM('P102'!$Q14:$S14)) -> 3.75 | Q14: 2.25 | R14: 1.5 | S14: 0 | T14: =IF(Q14<1.79,SUM(Q14:R14), SUM('P102'!$Q14:$S14)) -> 3.75 | U14: =('P102'!$L14+'P102'!$P14+'P102'!$T14)*'P102'!$F14 -> 5.625 | V14: 2.6 | W14: 6.42 | X14: =SUM('P102'!$V14:$W14)*'P102'!$G14 -> 4.51 | Y14: 0 | Z14: 1.5 | AA14: 1.25 | AB14: =IF(SUM('P102'!$Y14:$AA14)>5.9,"SI","NO") -> NO | AC14: =SUM('P102'!$Y14:$AA14) -> 2.75 | AD14: 1 | AE14: 4 | AF14: =IF('P102'!$AG14>5.9,"SI","NO") -> NO | AG14: =SUM('P102'!$AD14:$AE14) -> 5 | AH14: =IF('P102'!$AF14="NO",0," ") -> 0 | AI14: =IF('P102'!$AF14="NO",0," ") -> 0 | AJ14: =AVERAGE('P102'!$AH14:$AI14)*'P102'!$H14 -> 0 | AK14: 0 | AL14: 0 | AM14: 0 | AN14: =(1*('P102'!$AL14+'P102'!$AM14))*'P102'!$AK14 -> 0 | AO14: 7 | AP14: =SUM('P102'!$U14) -> 5.625 | AQ14: =SUM(AN14,AJ14,AG14,AC14,X14,('P102'!$AO14)*H14) -> 15.76 | AR14: ='P102'!$AP14+'P102'!$AQ14 -> 21.385
A15: migugala@espol.edu.ec | B15: 202509097 | C15: GALARZA MORA MIGUEL ANGEL | D15: 7 | F15: 0.98373875 | G15: 1.0293102 | H15: 0.5 | I15: 3 | J15: 2 | K15: 4.3 | L15: =IF(I15<1.79,SUM(I15:J15), SUM('P102'!$Q15:$S15)) -> 8.45 | M15: 3 | N15: 1.75 | O15: 3.7 | P15: =IF(M15<1.79,SUM(M15:N15), SUM('P102'!$Q15:$S15)) -> 8.45 | Q15: 3 | R15: 1.75 | S15: 3.7 | T15: =IF(Q15<1.79,SUM(Q15:R15), SUM('P102'!$Q15:$S15)) -> 8.45 | U15: =('P102'!$L15+'P102'!$P15+'P102'!$T15)*'P102'!$F15 -> 24.937777 | V15: 3.55 | W15: 7 | X15: =SUM('P102'!$V15:$W15)*'P102'!$G15 -> 10.859223 | Y15: 2 | Z15: 1.5 | AA15: 1.25 | AB15: =IF(SUM('P102'!$Y15:$AA15)>5.9,"SI","NO") -> NO | AC15: =SUM('P102'!$Y15:$AA15) -> 4.75 | AD15: 0 | AE15: 4 | AF15: =IF('P102'!$AG15>5.9,"SI","NO") -> NO | AG15: =SUM('P102'!$AD15:$AE15) -> 4 | AH15: =IF('P102'!$AF15="NO",0," ") -> 0 | AI15: =IF('P102'!$AF15="NO",0," ") -> 0 | AJ15: =AVERAGE('P102'!$AH15:$AI15)*'P102'!$H15 -> 0 | AK15: 0 | AL15: 0 | AM15: 0 | AN15: =(1*('P102'!$AL15+'P102'!$AM15))*'P102'!$AK15 -> 0 | AO15: 7.25 | AP15: =SUM('P102'!$U15) -> 24.937777 | AQ15: =SUM(AN15,AJ15,AG15,AC15,X15,('P102'!$AO15)*H15) -> 23.234223 | AR15: ='P102'!$AP15+'P102'!$AQ15 -> 48.172
A16: yodgonza@espol.edu.ec | B16: 202410247 | C16: GONZALEZ SANCAN YODER ARIEL | D16: 4 | F16: 0.5 | G16: 0.5 | H16: 0.5 | I16: 2.25 | J16: 1 | K16: 4.5 | L16: =IF(I16<1.79,SUM(I16:J16), SUM('P102'!$Q16:$S16)) -> 3.75 | M16: 2.25 | N16: 1.5 | O16: 0 | P16: =IF(M16<1.79,SUM(M16:N16), SUM('P102'!$Q16:$S16)) -> 3.75 | Q16: 2.25 | R16: 1.5 | S16: 0 | T16: =IF(Q16<1.79,SUM(Q16:R16), SUM('P102'!$Q16:$S16)) -> 3.75 | U16: =('P102'!$L16+'P102'!$P16+'P102'!$T16)*'P102'!$F16 -> 5.625 | V16: 2.6 | W16: 6.43 | X16: =SUM('P102'!$V16:$W16)*'P102'!$G16 -> 4.515 | Y16: 1 | Z16: 1.5 | AA16: 0 | AB16: =IF(SUM('P102'!$Y16:$AA16)>5.9,"SI","NO") -> NO | AC16: =SUM('P102'!$Y16:$AA16) -> 2.5 | AD16: 1 | AE16: 4 | AF16: =IF('P102'!$AG16>5.9,"SI","NO") -> NO | AG16: =SUM('P102'!$AD16:$AE16) -> 5 | AH16: =IF('P102'!$AF16="NO",0," ") -> 0 | AI16: =IF('P102'!$AF16="NO",0," ") -> 0 | AJ16: =AVERAGE('P102'!$AH16:$AI16)*'P102'!$H16 -> 0 | AK16: 0 | AL16: 0 | AM16: 0 | AN16: =(1*('P102'!$AL16+'P102'!$AM16))*'P102'!$AK16 -> 0 | AO16: 0 | AP16: =SUM('P102'!$U16) -> 5.625 | AQ16: =SUM(AN16,AJ16,AG16,AC16,X16,('P102'!$AO16)*H16) -> 12.015 | AR16: ='P102'!$AP16+'P102'!$AQ16 -> 17.64
A17: rhasague@espol.edu.ec | B17: 202505954 | C17: GUERRA SALGUERO RHANDOL SAUL | D17: 5 | F17: 0.5 | G17: 0.5 | H17: 0.5 | I17: 2.25 | J17: 2 | K17: 3.5 | L17: =IF(I17<1.79,SUM(I17:J17), SUM('P102'!$Q17:$S17)) -> 7.45 | M17: 2.25 | N17: 1.5 | O17: 3.7 | P17: =IF(M17<1.79,SUM(M17:N17), SUM('P102'!$Q17:$S17)) -> 7.45 | Q17: 2.25 | R17: 1.5 | S17: 3.7 | T17: =IF(Q17<1.79,SUM(Q17:R17), SUM('P102'!$Q17:$S17)) -> 7.45 | U17: =('P102'!$L17+'P102'!$P17+'P102'!$T17)*'P102'!$F17 -> 11.175 | V17: 2.85 | W17: 6.6 | X17: =SUM('P102'!$V17:$W17)*'P102'!$G17 -> 4.725 | Y17: 1.5 | Z17: 1.5 | AA17: 0 | AB17: =IF(SUM('P102'!$Y17:$AA17)>5.9,"SI","NO") -> NO | AC17: =SUM('P102'!$Y17:$AA17) -> 3 | AD17: 0 | AE17: 2 | AF17: =IF('P102'!$AG17>5.9,"SI","NO") -> NO | AG17: =SUM('P102'!$AD17:$AE17) -> 2 | AH17: =IF('P102'!$AF17="NO",0," ") -> 0 | AI17: =IF('P102'!$AF17="NO",0," ") -> 0 | AJ17: =AVERAGE('P102'!$AH17:$AI17)*'P102'!$H17 -> 0 | AK17: 0 | AL17: 0 | AM17: 0 | AN17: =(1*('P102'!$AL17+'P102'!$AM17))*'P102'!$AK17 -> 0 | AO17: 7.25 | AP17: =SUM('P102'!$U17) -> 11.175 | AQ17: =SUM(AN17,AJ17,AG17,AC17,X17,('P102'!$AO17)*H17) -> 13.35 | AR17: ='P102'!$AP17+'P102'!$AQ17 -> 24.525
A18: ghidrovo@espol.edu.ec | B18: 202205944 | C18: HIDROVO ZAMBRANO GENESIS ROSALINDA | D18: 3 | F18: 1.1547005 | G18: 1.1547005 | H18: 1.1547005 | I18: 2.25 | J18: 1.25 | K18: 4.75 | L18: =IF(I18<1.79,SUM(I18:J18), SUM('P102'!$Q18:$S18)) -> 8.6 | M18: 3 | N18: 2 | O18: 3.6 | P18: =IF(M18<1.79,SUM(M18:N18), SUM('P102'!$Q18:$S18)) -> 8.6 | Q18: 3 | R18: 2 | S18: 3.6 | T18: =IF(Q18<1.79,SUM(Q18:R18), SUM('P102'!$Q18:$S18)) -> 8.6 | U18: =('P102'!$L18+'P102'!$P18+'P102'!$T18)*'P102'!$F18 -> 29.791274 | V18: 4.15 | W18: 8.1 | X18: =SUM('P102'!$V18:$W18)*'P102'!$G18 -> 14.145082 | Y18: 2 | Z18: 1.5 | AA18: 2.5 | AB18: =IF(SUM('P102'!$Y18:$AA18)>5.9,"SI","NO") -> SI | AC18: =SUM('P102'!$Y18:$AA18) -> 6 | AD18: 1 | AE18: 6 | AF18: =IF('P102'!$AG18>5.9,"SI","NO") -> SI | AG18: =SUM('P102'!$AD18:$AE18) -> 7 | AH18: 4 | AI18: 3.5 | AJ18: =AVERAGE('P102'!$AH18:$AI18)*'P102'!$H18 -> 4.330127 | AK18: 1 | AL18: 7 | AM18: 7 | AN18: =(1*('P102'!$AL18+'P102'!$AM18))*'P102'!$AK18 -> 14 | AO18: 9.25 | AP18: =SUM('P102'!$U18) -> 29.791274 | AQ18: =SUM(AN18,AJ18,AG18,AC18,X18,('P102'!$AO18)*H18) -> 56.156189 | AR18: ='P102'!$AP18+'P102'!$AQ18 -> 85.947462
A19: jermorei@espol.edu.ec | B19: 202405767 | C19: LEON MOREIRA JEREMY ALEXANDER | D19: 7 | F19: 0.5 | G19: 1.05605 | H19: 0.5 | I19: 2.25 | J19: 2 | K19: 4.3 | L19: =IF(I19<1.79,SUM(I19:J19), SUM('P102'!$Q19:$S19)) -> 4 | M19: 2.25 | N19: 1.75 | O19: 0 | P19: =IF(M19<1.79,SUM(M19:N19), SUM('P102'!$Q19:$S19)) -> 4 | Q19: 2.25 | R19: 1.75 | S19: 0 | T19: =IF(Q19<1.79,SUM(Q19:R19), SUM('P102'!$Q19:$S19)) -> 4 | U19: =('P102'!$L19+'P102'!$P19+'P102'!$T19)*'P102'!$F19 -> 6 | V19: 3.55 | W19: 7 | X19: =SUM('P102'!$V19:$W19)*'P102'!$G19 -> 11.141328 | Y19: 1.5 | Z19: 0 | AA19: 0 | AB19: =IF(SUM('P102'!$Y19:$AA19)>5.9,"SI","NO") -> NO | AC19: =SUM('P102'!$Y19:$AA19) -> 1.5 | AD19: 0 | AE19: 4 | AF19: =IF('P102'!$AG19>5.9,"SI","NO") -> NO | AG19: =SUM('P102'!$AD19:$AE19) -> 4 | AH19: =IF('P102'!$AF19="NO",0," ") -> 0 | AI19: =IF('P102'!$AF19="NO",0," ") -> 0 | AJ19: =AVERAGE('P102'!$AH19:$AI19)*'P102'!$H19 -> 0 | AK19: 0 | AL19: 0 | AM19: 0 | AN19: =(1*('P102'!$AL19+'P102'!$AM19))*'P102'!$AK19 -> 0 | AO19: 7.25 | AP19: =SUM('P102'!$U19) -> 6 | AQ19: =SUM(AN19,AJ19,AG19,AC19,X19,('P102'!$AO19)*H19) -> 20.266328 | AR19: ='P102'!$AP19+'P102'!$AQ19 -> 26.266328
